Workbook

Sheet comparison
A1: Grant ID | B1: Title | C1: Abstract | D1: scope | E1: scope_LLM | F1: confidence_LLM | G1: reasoning_LLM | H1: correct_scope | I1: pillar | J1: pillar_LLM | K1: correct_pillar | L1: plant_based_LLM | M1: fermentation_LLM | N1: cultivated_LLM | O1: cross_cutting_LLM | P1: status | Q1: error
A2: grant.14917108 | B2: Scientific Exchange to assess QUality and Risks of FOODs obtained by novel processing and PackagingTechnologies | C2: The goal of SEQUR FOOD is to build an international scientific network including researchers from EU and South America that will work on the development of novel food processing technologies, (i.e. UV treatment, cold plasma processing, nanoemulsification, freeze concentration and drying) and/or active bioactive packaging (i.e. bacterial cellulose, antibacterial paper, etc.) to obtain safe products for the EU market with higher shelf-life and high nutritional and functional properties. This includes optimization of the novel food processing technologies, nutritional and risk assessment of these technologies and obtained products as novel foods within EFSA’s framework, and documenting their health claims, if relevant. To achieve this objective, a consortium of 5 universities from EU (Greece, Poland, Romania, and Spain) with expertise in all the aspects of EU risk assessment, 1 plant-based products processing company based in Poland together with 1 university and 1 research institute from South America (Colombia) with extended expertise in novel food processing techniques will work on a variety of case studies spread across several novel food processing technologies and products relevant for Colombia: fruit (passionfruit, uchuva (Physalis peruviana L.), blueberries); cold brewed coffee; oat milk (including oat grains and nuts needed for its production); and high oleic palm oil as compared to olive oil. These case studies will be a proof of concept for the holistic assessment of each technology-foodstuff pair and will constitute the basis for further research, but also for food processors, the principal stakeholders of the project. The activities proposed in SEQUR FOOD are innovative in many aspects. The most important innovation is the holistic approach of new food product development in terms of the complete physico-chemical, microbiological, nutritional and functional properties, but also sensory evaluation and multicultural consumer acceptance. | D2: out | E2: out | F2: 2 | G2: Although the project includes oat milk as a case study, the research focuses on novel food processing and packaging technologies for food safety and shelf-life across a broad range of products (fruits, coffee, palm oil), with no stated focus on alternative protein development or substitution of animal-derived products. | H2: =TRUE() -> TRUE | I2: NA | J2: NA | K2: =TRUE() -> TRUE | L2: =FALSE() -> FALSE | M2: =FALSE() -> FALSE | N2: =FALSE() -> FALSE | O2: =FALSE() -> FALSE | P2: ok
A3: grant.15145414 | B3: VegVit | C3: "VegVit" is een interdisciplinair project dat gericht is op de ontwikkeling van een assortiment veganistische zuivel- en vleesalternatieven met een verbeterd nutritioneel profiel (vitamine B12, maar ook proteïnekwaliteit/breder aminozuurprofiel). Het eerste concrete doel van het project is dat voedselveilige starterculturen geïdentificeerd en geselecteerd kunnen worden die onder geschikte omstandigheden hoge niveaus van vitamine B12 vormen. Het tweede concrete doel is dat vitamine B12-verrijkte ingrediënten geproduceerd kunnen worden door eerst grondstoffen zoals geëxtrudeerde plantaardige eiwitten of eiwitsuspensies te fermenteren. Deze verrijkte ingrediënten kunnen vervolgens in een tweede stap worden omgezet in hoogwaardige analogen met verhoogde B12-gehaltes en een beter proteïnekwaliteit. Het derde concrete doel is dat vitamine B12 in-situ gevormd wordt via een co-fermentatieproces, door tijdens het productieproces van salami- yoghurt- of smeerkaasanalogen geschikte starterculturen toe te voegen. Afhankelijk van de aard en samenstelling van de matrix (geselecteerde ingrediënten, homogene of heterogene matrix structuur, pH, wateractiviteit) kan de ene aanpak voordeliger zijn dan de andere. Hierbij ligt de focus op het creëren van producten die zowel in kwaliteit als voedingswaarde voldoen aan de verwachtingen van de consument. | D3: in | E3: in | F3: 7 | G3: This project explicitly develops vegan dairy and meat analogues (salami, yoghurt, cheese analogues) using fermentation of plant-based proteins to improve nutritional profile (vitamin B12 and protein quality), directly advancing alternative protein product development. | H3: =TRUE() -> TRUE | I3: PB | J3: CC | K3: =FALSE() -> FALSE | L3: =TRUE() -> TRUE | M3: =TRUE() -> TRUE | N3: =FALSE() -> FALSE | O3: =FALSE() -> FALSE | P3: ok | R3: Acceptable as CC, but PB preferred.
A4: grant.14631940 | B4: Growing well Study (GWS): the role of portion size, plant-based foods and commercially manufactured foods and drinks | C4: What are the study aims? To understand more about eating habits of children aged 1-5 years old, and how this affects their growth and dental health. We also want to find age-appropriate food/drink portion sizes. Why is this research important? Healthy diets in early years are important for growth and development. However, it is difficult to give parents clear guidance on what and how much children should eat due to lack of up-to-date information. Commercially manufactured foods/drinks for young children are often high in free sugars, salt, and fat. Plant-based diets (PBDs) may also be low in important nutrients. What will we do? Part 1: Collect data on foods/nutrients/dietary patterns of children to determine optimum growth and dental health At baseline, parents of children aged 1-5 years from Leeds, Doncaster and East London will complete questionnaires about their child s food intake. They will be asked to record what their child has eaten for three one-day periods across 6 months using an online system called myfood24 . This has a large commercial product database with child-appropriate portion sizes. Parents will also attend one in-person session with their child. Children s length/height, weight, and head circumference will be measured at local children s centres/nurseries or in homes. We will ask these same people to complete surveys again one year later, with another measurement session to look at growth. We will also assess dental health to identify healthy and decayed teeth. Part 2: Analyse the results of surveys and measurements We want to understand how growth and dental health are influenced by nutrient intakes (e.g. sugar or fat), diet pattern (vegetarian/vegan/dairy free), and portion sizes for key food groups. We will identify how much of different foods children should be eating for their age. We can also find out whether commercial foods designed for children are needed. How will parents be involved? Our parent advisors have provided input to this summary and helped in study design including planning how best to collect information and engage with participants. We will create a Parent Advisory Group in Leeds/Doncaster/East London. Representatives will form part of the Project Steering Committee. What do we expect to achieve and what happens next? We will identify the optimum nutrient composition of diets to support healthier children; and how sub-optimal intakes in vulnerable groups may be redressed. Guidelines will be developed to help parents and policy-makers promote age-appropriate portion sizes of foods. We will also know whether contemporary vegetarian/vegan/non-dairy dietary patterns can support optimum growth. New guidance will be provided on caring for children s teeth. Our findings will be shared in written reports, through a social media/media campaign to promote guidelines; plus visual storytelling feedback for participants and key influencer groups.Research question We will answer questions posed by the recent Scientific Advisory Committee on Nutrition (SACN) report: What are age-appropriate food and drink portion sizes in relation to growth and dental health? What are the short-term effects (12 months) on growth and dental health of commercial foods for children; vegetarian/vegan/dairy-free dietary patterns? What is the impact on growth and dental health of macro- and micro-nutrient intakes; fruit juices/free sugars; formula milks for 12m+; sweeteners? Background In the UK, little contemporary data exists on diet in young children but worrying trends in preschool overweight and dental health are reported. Current young child diets do not meet dietary recommendations and evidence-driven age-appropriate portion size recommendations are missing. Further research into the impact of plant-based diets, the use of commercial foods, and toddler milks is also recommended by SACN. Aims and Objectives To provide new evidence on diet in children aged 1-5y, linked to optimum growth and dental health. Quantifying age-appropriate portion sizes for different foods and drinks. Collect data on child dietary intake, portion sizes. Collect data on parent and child attributes, including child anthropometrics and dental health. Evaluate food and nutrient intake in relation to i) growth over 12 months, ii) child and parent characteristics, including ethnic diversity, deprivation and iii) dental health. Make recommendations for nutrition and age-appropriate portions. Methods We will recruit 2100 parents of young children (1-5years) through the Born and Bred in (BaBi) Network birth cohorts in Leeds, Doncaster, and East London. Recruitment will include at least 400 in each year bracket, 20% non-white, 20% from deprived locations, and 300 (15%) vegetarian/vegan/non-dairy diet. Plans are in place to ensure recruitment targets are met. Protocols, consent forms, and questionnaires will be co-designed with our Parent Advisory Group. Baseline data will be collected using i) online survey, ii) face-to-face growth measures of height, weight, length, head circumference iii) 3 x 24h measures of diet spanning 6 months. Follow-up data collected after 12 months will repeat baseline measures and include a dental assessment. Cross-sectional and longitudinal analysis will explore how growth and dental health are influenced by nutrient intakes, diet pattern, and food portion sizes. Age/gender appropriate portion sizes for key food groups will be characterised with linear mixed-effects modelling for specific foods/food groups in relation to the child s position on the growth chart centiles. Timelines Month 3 Study start (ethics, questionnaires etc.) completed. Month 5 Pilot test. Months 6-12 baseline data collection. Month 18 all baseline diet information collected. Months 19- 24 follow-up data collected. Month 36 analysis and write up complete. Anticipated Impact and Dissemination Knowledge of associations between food and nutrient intakes and growth/dental health and knowledge of suboptimal intakes in vegan/vegetarian/dairy-free or vulnerable groups will enable evidence-based guidelines on age-appropriate portion sizes and optimal diet composition. Guideline promotion to key stakeholders and visual feedback to participants will support intake of age-appropriate portions and healthier diets. Ultimately resulting in healthier children, with better dental health. Guidelines will also highlight social inequalities, indicating specific actions to redress imbalances. | D4: out | E4: out | F4: 2 | G4: This study examines dietary habits and growth outcomes in young children, including vegetarian/vegan/dairy-free diets, but focuses on general nutritional epidemiology rather than the development, characterisation, or societal aspects of alternative protein products specifically. | H4: =TRUE() -> TRUE | I4: NA | J4: NA | K4: =TRUE() -> TRUE | L4: =FALSE() -> FALSE | M4: =FALSE() -> FALSE | N4: =FALSE() -> FALSE | O4: =FALSE() -> FALSE | P4: ok
A5: grant.15060106 | B5: "Een Exclusieve Duurzaamheidstransitie van de Mode? Hoe Culturele Duurzaamheidsentrepreneurs in Culturele Industrieën Klimaatpolarisatie Riskeren" | C5: Dit project neemt de ecologisch destructieve case van mode om te bestuderen hoe belangrijke klimaatvoorvechters in culturele industrieën, zoals groene influencers, mogelijk bijdragen aan polarisatie door burgers met andere achtergronden en opvattingen over duurzaamheid uit te sluiten en te moraliseren. Aangezien de cultuursociologie aantoont dat culturele industrieën gedomineerd worden door witte hogere middenklassen, en klimaatsociologie waarschuwt dat hun klimaatbenadering moraliserend is, verwacht dit project dat duurzaamheid in culturele velden gericht is op de 'havermelkelite', met mogelijke polarisatie en klimaattegenslag tot gevolg. Door deze perspectieven uit de cultuursociologie, klimaatsociologie en politicologie te verbinden, toont dit project (1) wie, in termen van sociaal, cultureel en economisch kapitaal, het duurzaamheidsframe in de mode bepalen, (2) in welke mate en hoe ze burgers met minder kapitaal en andere duurzaamheidsbenaderingen moraliseren en uitsluiten (3) hoe dit leidt tot affectieve polarisatie tot ver buiten de mode. Door kwalitatieve en kwantitatieve methoden te combineren, bestudeert dit project deze vragen in 3 Europese landen (België, Zweden en Italië) met nadruk op sociale media, de plek voor de discursieve constructie van duurzaamheid in de mode en daarbuiten. Dit project toont zo hoe de ongelijkheden van culturele productie uitsluiting en polarisatie rond de klimaatcrisis veroorzaakt en legt de culturele wortels van klimaatpolarisatie bloot. | D5: out | E5: out | F5: 1 | G5: This grant concerns the sociology of sustainability in the fashion industry, studying climate polarisation and cultural inequality — it has no connection to alternative proteins or food science. | H5: =TRUE() -> TRUE | I5: NA | J5: NA | K5: =TRUE() -> TRUE | L5: =FALSE() -> FALSE | M5: =FALSE() -> FALSE | N5: =FALSE() -> FALSE | O5: =FALSE() -> FALSE | P5: ok
A6: grant.15150934 | B6: From Potato Waste to Mycoprotein – A Sustainable Food Innovation | C6: This project aims to upcycle food-grade potato side streams from Orkla, into protein-rich food ingredients via solid-state fermentation with the filamentous fungus Fusarium venenatum (used in Quorn). The resulting mycoprotein is a biomass high in protein and fiber that can serve as a sustainable meat alternative. Our approach tackles two challenges simultaneously: reducing food waste by valorizing agro-industrial by-products, and creating new climate-friendly protein sources. A prior proof-of-concept demonstrated that Fusarium can effectively grow on potato and significantly increase their protein content. Building on this foundation, the plan is to develop the fermentation process further, enabling the next step of implementing the process in pre-pilot scale utilising Biotech Heights, with Orkla, providing side streams in-kind and help align the research with relevant conditions. The project will deliver optimized fermentation protocols, comparisons of different reactor designs, nutritional and sensory evaluation of the resulting protein, and prototype food products incorporating it. The expected outcomes will show a circular “food-from-food-waste” model in which potato residues are converted into a valuable protein ingredient. This aligns with the objectives of the national research program on Food and Climate by developing resource-efficient, circular production systems that reduce environmental impact while enhancing sustainable food supply and industry competitiveness. | D6: in | E6: in | F6: 7 | G6: This grant directly concerns biomass fermentation using Fusarium venenatum (the organism used in Quorn mycoprotein) on potato side streams to produce a protein-rich meat alternative ingredient, which is clearly within the fermentation alternative protein category. | H6: =TRUE() -> TRUE | I6: F | J6: F | K6: =TRUE() -> TRUE | L6: =FALSE() -> FALSE | M6: =TRUE() -> TRUE | N6: =FALSE() -> FALSE | O6: =FALSE() -> FALSE | P6: ok
A7: grant.14933116 | B7: Flexible and Efficient Capture and Bioconversion of CO2 to Materials and Ingredients | C7: The UNICO2RN project aims to demonstrate novel routes to convert biogenic CO2 into ingredients and materials, involving metal organic framework-based capture and purification technology and biotechnological processes based on Hydrogen Oxidizing Bacteria. The modularity and flexibility of the developed processes will be shown through 2 demonstration cases in real industrial settings at TRL 7 for sustainable and efficient production of microbial proteins and PHA, from 2 types of biogenic CO2 sources of different concentration and purity. These new routes bring clear advantages in terms of efficiency, safety, environmental footprint and greenhouse gas emission reductions with respect to benchmarks. Their development to TRL7 will enable their industrialization and thus lead to major positive economic, environmental and social/societal impacts. | D7: in | E7: in | F7: 6 | G7: The project involves Hydrogen Oxidizing Bacteria to produce microbial proteins (single-cell protein via biomass fermentation), which is an alternative protein production method within the fermentation category. | H7: =TRUE() -> TRUE | I7: F | J7: F | K7: =TRUE() -> TRUE | L7: =FALSE() -> FALSE | M7: =TRUE() -> TRUE | N7: =FALSE() -> FALSE | O7: =FALSE() -> FALSE | P7: ok
A8: grant.15162658 | B8: FUNGAL SINGLE CELL PROTEIN FROM MACROALGAL WASTE FERMENTATION: IMPROVING SUSTAINABILITY AND REDUCING THE CARBON FOOTPRINT OF FISH AQUAFEEDS | C8: ALFUNFEED BUSCA TRANSFORMAR LA PRODUCCION DE ALIMENTOS ACUICOLAS MEDIANTE PROCESOS BIOTECNOLOGICOS INNOVADORES. SU OBJETIVO PRINCIPAL ES SUSTITUIR LAS FUENTES DE PROTEINA VEGETAL (PP) EN ALIMENTOS ACUICOLAS PARA ESPECIES DE PECES CARNIVOROS POR PROTEINA UNICELULAR (SCP) DERIVADA DE LA FERMENTACION FUNGICA DE SUSTRATOS A BASE DE MACROALGAS. ALFUNFEED SE BASA EN UN ENFOQUE MULTIDISCIPLINARIO QUE APROVECHA LA EXPERIENCIA DE DIVERSOS CAMPOS. LA FASE INICIAL, LIDERADA POR ODS, SE CENTRA EN EL DESARROLLO DE SCP A PARTIR DE TRES CEPAS DE HONGOS FILAMENTOSOS (NEUROSPORA CRASSA, RHIZOPUS ORYZAE Y FUSARIUM VENENATUM), CONSIDERANDO CUATRO VARIABLES DE PRODUCCION (TEMPERATURA, PH, OXIGENACION Y COMPOSICION DEL MEDIO), LO QUE DA COMO RESULTADO TRES SCP QUE SUSTITUYEN EL 15 % DE PP EN LAS DIETAS DE LUBINA (DICENTRARCHUS LABRAX), COMO MODELO DE ESPECIES DE PECES CARNIVOROS. CON LAS CONDICIONES OPTIMAS DEFINIDAS, SE FORMULARAN TRES DIETAS CON SCP DE CADA CEPA PARA ALIMENTAR A JUVENILES DE LUBINA EN UN ESTUDIO PILOTO QUE INCLUYE PRUEBAS DE ALIMENTACION Y EVALUACION DEL ESTADO INMUNITARIO (CIIMAR), REGULACION DE LA INGESTA DE ALIMENTO, PERFIL NUTRICIONAL Y FUNCION DIGESTIVA (UVIGO), MICROBIOTA INTESTINAL (UTH) Y BIENESTAR DE LOS PECES (UNIVPM). EL SCP MAS PROMETEDOR DEL ESTUDIO PILOTO SE SOMETERA A UN ESTUDIO DE VALIDACION SEGUN LAS RECOMENDACIONES DE LA EFSA CON DIFERENTES NIVELES DE SUSTITUCION DE PP (15-25%) PARA DETERMINAR LA SUSTITUCION OPTIMA SIN COMPROMETER LA ROBUSTEZ DE LOS PECES. TAMBIEN SE EVALUARA EL ANALISIS DE COSTES Y EL IMPACTO AMBIENTAL DEL SCP Y LA PRODUCCION DE ALIMENTOS ACUICOLAS INTEGRALES. LOS SOCIOS DEL CONSORCIO, PROCEDENTES DE PAISES EUROPEOS CLAVE EN ACUICULTURA (GRECIA, ESPAÑA, ITALIA Y PORTUGAL), QUE REPRESENTAN LAS CUENCAS MEDITERRANEA Y ATLANTICA, BUSCAN GENERAR INFORMACION Y DATOS VALIOSOS QUE BENEFICIEN LAS PRACTICAS ACUICOLAS A NIVEL MUNDIAL. ESTE ESFUERZO COLABORATIVO ENCARNA EL MODELO DE LA CUADRUPLE HELICE, INVOLUCRANDO AL MUNDO ACADEMICO, LA INDUSTRIA, EL GOBIERNO Y LA SOCIEDAD CIVIL PARA IMPULSAR EL SECTOR ACUICOLA HACIA LA SOSTENIBILIDAD Y LA RESILIENCIA. EL PROYECTO ENFATIZA LOS PRINCIPIOS DE SOSTENIBILIDAD Y ECONOMIA CIRCULAR AL VALORIZAR LOS DESCARTES DE MACROALGAS COMO UN RECURSO VALIOSO PARA LA PRODUCCION DE SCP. ALFUNFEED CONTRIBUYE AL DESARROLLO DE UNA ECONOMIA OCEANICA MAS EQUITATIVA Y RESPETUOSA CON EL MEDIO AMBIENTE, ALINEANDOSE CON LOS DESAFIOS ESPECIFICOS DESCRITOS EN EL DECENIO DE LAS NACIONES UNIDAS DE LAS CIENCIAS OCEANICAS, COMO EL DESARROLLO SOSTENIBLE DE LA ECONOMIA OCEANICA Y LA SEGURIDAD ALIMENTARIA MUNDIAL, ABORDANDO ASI PROBLEMAS GLOBALES CRITICOS. ALFUNFEED TAMBIEN PRIORIZA LAS ACTIVIDADES DE SENSIBILIZACION Y PARTICIPACION PARA PROMOVER LA CULTURA OCEANICA Y LAS PRACTICAS ACUICOLAS RESPONSABLES. A TRAVES DE INICIATIVAS DE DIFUSION, EL PROYECTO BUSCA LLEGAR A PUBLICOS DIVERSOS Y FOMENTAR UNA COMPRENSION MAS PROFUNDA DE LA IMPORTANCIA DE LA PRESERVACION DE LOS RECURSOS MARINOS. LA IMPLEMENTACION EXITOSA DE ALFUNFEED PODRIA CONDUCIR A LA ADOPCION GENERALIZADA DE FORMULAS DE ALIMENTOS ACUICOLAS SOSTENIBLES A ESCALA INDUSTRIAL. SE HAN IMPLEMENTADO ESTRATEGIAS INTEGRALES DE DIFUSION Y GESTION DE LA PROPIEDAD INTELECTUAL PARA GARANTIZAR LA EXPLOTACION RESPONSABLE DE LOS RESULTADOS DEL PROYECTO, MAXIMIZANDO SU IMPACTO Y FACILITANDO LA TRANSICION HACIA UN SECTOR ACUICOLA MAS SOSTENIBLE. | D8: out | E8: out | F8: 1 | G8: This grant focuses on producing fungal single-cell protein from macroalgal waste for use in aquafeeds (fish feed) for carnivorous fish species, which is explicitly a non-human food/aquafeed application and therefore out of scope. | H8: =TRUE() -> TRUE | I8: NA | J8: NA | K8: =TRUE() -> TRUE | L8: =FALSE() -> FALSE | M8: =FALSE() -> FALSE | N8: =FALSE() -> FALSE | O8: =FALSE() -> FALSE | P8: ok
A9: grant.15166434 | B9: Sustainable production of microbial proteins and their application in value-added cereal goods manufacturing | C9: As demand for animal origin food products increases faster than a global production can offer, novel strategies for carbon-neutral food manufacturing are an important part for diversifying food products and ensuring food self-sufficiency. Nowadays, more than one-fifth of global greenhouse gas emissions come from agriculture. Therefore, the development of alternative proteins and their adoption by consumers is critical to reduce negative climate change. Although plant-based alternatives make up 99% of this market, and most other proteins types (insects or microbes) are still in research and development pushing their greater commercialization at the end of this decade. The market with microbial proteins will be driven mainly by the expected increase in the world population, associated with countries' effort to secure food self-sufficiency and current trends in food consumption, which won’t be reachable by conventional agriculture/economy. Among the advantages of microbial proteins is their simple production, which includes a very short production time compared to the duration of growing crops, or raising animals, and also lower land and water requirements. Moreover, already available and producible mycoproteins (used as whole-cell products; without necessity of protein concentration or isolation) contain 40 % protein, have a high fibre content, limited saccharides content and don’t contain cholesterol, which makes them nutritionally more interesting compared to „classic“ proteins. The presented project focuses on potential production of microbial proteins using filamentous fungi and yeast by utilization of waste byproducts from industry. The main waste side-stream would be corn mash (form ethanol production) and glycerol (from biodiesel production). Returning of such waste into production has significant environmental effect. Furthermore, the produced biomass will be employed into process of bakery good production. Thus the effect of usage of these alternative would b | D9: in | E9: in | F9: 7 | G9: The grant focuses on biomass fermentation using filamentous fungi and yeast to produce microbial proteins (mycoprotein) as alternative protein ingredients for food applications, which is clearly within scope. | H9: =TRUE() -> TRUE | I9: F | J9: F | K9: =TRUE() -> TRUE | L9: =FALSE() -> FALSE | M9: =TRUE() -> TRUE | N9: =FALSE() -> FALSE | O9: =FALSE() -> FALSE | P9: ok
A10: grant.14933075 | B10: Upcycling mushroom waste to replace animal derived chemicals | C10: Animal-derived materials are surprisingly widespread in everyday products. For example, in the cosmetics, pharmaceutical and agrochemicals industries, squalene (from shark liver oil), chitin/chitosan (from crustaceans) and animal-derived proteins and fats are widely exploited despite growing ethical and sustainability concerns. Fungal biomass is rich in chitin, while recent advances in fermentation technologies offer opportunities to convert fungal glucans into microbial proteins, oils and even triterpenes such as squalene. However, scalability is a major challenge, due to the limited availability of clean fungal biomass and competition with food/feed value chains. Moreover, oil production using existing fungal fermentation routes is limited to low-value triglycerides, and efficient product extraction remains a bottleneck. Feedstock diversification is needed, alongside innovation towards higher-value products and more efficient processes. The production of edible mushrooms produces ~189M tpa of mycelium rich wastes, contaminated with lignocellulosic growth substrate. This contamination makes these wastes unsuitable for food/feeds, and incompatible with existing valorisation approaches. MYCOCIRCLE will focus on this challenging feedstock, developing new technologies including an enzymatic fractionation process, two parallel fermentation routes, and novel enzymatic chitin conversion reactions. The resulting product streams, including fungal chitosan/chito-oligosaccharides, a high-value squalene-rich microbial oil, and microbial proteins, will be validated as replacements to animal derived materials in cosmetic and agrochemical applications. The MYCOCIRCLE consortium represents the entire value chain, from feedstock producers (SYLVAN, KORONA) to industrial biotechnology companies (GST), and end users (GI, THGL). This value chain will be supported by world experts in biomass valorisation, enzymatic processing, and SSbD development: TUM, SINTEF, NMBU, SLU and IDENER. | D10: out | E10: out | F10: 2 | G10: The grant focuses on upcycling mushroom waste to produce chitin/chitosan, squalene-rich oils, and microbial proteins for cosmetic and agrochemical applications — not for human food or as substitutes for animal-derived food products. | H10: =TRUE() -> TRUE | I10: NA | J10: NA | K10: =TRUE() -> TRUE | L10: =FALSE() -> FALSE | M10: =FALSE() -> FALSE | N10: =FALSE() -> FALSE | O10: =FALSE() -> FALSE | P10: ok
A11: grant.14486646 | B11: Rim-kinases in fungal secondary metabolism and pathogenicity | C11: Molds play a variety of ecological roles on our planet, especially in natural nutrient cycles and as pathogens of plants and animals. Of particular interest is their ability to produce a wide variety of small, bioactive molecules. One example of a very useful molecule is the antibiotic penicillin, which has saved millions of lives to date. But there are also dangerous molecules, such as toxins produced by molds, that can contaminate our food and thereby threaten consumer health. So the final goal must be to precisely understand the molecular and cellular programs in those fungi and thus develop natural solutions against fungal infections. Our previous research has shown that epigenetic processes regulate toxin production, but also a specific kinase - a regulatory protein that can chemically modify other proteins in its environment - plays a decisive role. In a previously unknown way, it is able to transmit a starvation signal in the cell, which ultimately leads to a complete change in the cellular metabolism and thereby activates the genetic machinery for toxin formation. In this project, we are now addressing the question of exactly how the starvation signal is processed by the fungal cell so that mycotoxins are formed. For this, we are using as experimental systems a conventional mold that is present ubiquitously in nature and buildings (Aspergillus) and a fungus that is considered one of the most important pathogens in crop plants worldwide (Fusarium). The entire genetic response of both fungi at the RNA level and at the protein level will be analyzed molecularly, biochemically and bioinformatically during different stages of their life cycles. In addition, those proteins whose function is regulated by the kinase should be identified. In this way, the signaling pathway from nutrient deficiency from the cell surface to the genetic activation of toxin production in two different molds should be elucidated as completely as possible. Ultimately, the results of this research could close a gap in the fundamental understanding of cellular processes during toxin production in mold fungi. This knowledge can then be used to develop new control strategies to ward off plant diseases and prevent biological contamination of food. | D11: out | E11: out | F11: 1 | G11: This grant concerns fungal pathogenicity and mycotoxin production mechanisms in Aspergillus and Fusarium, with no connection to alternative protein development or production. | H11: =TRUE() -> TRUE | I11: NA | J11: NA | K11: =TRUE() -> TRUE | L11: =FALSE() -> FALSE | M11: =FALSE() -> FALSE | N11: =FALSE() -> FALSE | O11: =FALSE() -> FALSE | P11: ok
A12: grant.14878552 | B12: Designing a professional-secretory synthetic endoplasmic reticulum in yeasts and plant cells | C12: The endoplasmic reticulum (ER) is the key organelle for folding and processing of secretory proteins. Inefficient folding and secretion are a major challenge in production of recombinant proteins needed as biopharmaceuticals or for securing future food requirements. In most non-mammalian cells, the ER is spatially limiting these processes. SynthER aims to go beyond mere physical ER expansion by tailoring functionality through orthogonal and combinatorial expression of synthetic ER shaping proteins in yeast and plant cells. Inspired by professional secretory mammalian cells, SynthER envisages to biomimic their stacked ER sheet and luminal architecture in yeast and plants. The new morphologies will be monitored by a wide range of microscopic methods and quantitative image analyses, and their impact on the quality and quantity of secreted recombinant proteins will be determined.Furthermore, synthetic ER exit vesicles (SERV) will be designed to deliver their protein cargo directly to the plasma membrane, bypassing the often adverse functions of the Golgi and vacuole. SERVs shall be programmable synthetic circuits, that can be expressed on demand.Taken together, SynthER will develop novel cell factory concepts that represent a significant advance to the state of the art. Synthetic endomembrane engineering addresses a timely research topic through a pioneering synthetic biology approach with significant potential for advancing both the scientific understanding of secretory pathway plasticity and impacting technological applications, thus benefiting medicine and biotechnology.Our ground-breaking interdisciplinary combination of cross-kingdom molecular and cell biology in microbes and whole plants together with advanced microscopy and engineering unlocks new scientific opportunities and expands the toolkit of synthetic cellular design. | D12: out | E12: out | F12: 2 | G12: This grant focuses on engineering the endoplasmic reticulum in yeast and plant cells to improve recombinant protein secretion for biopharmaceutical and general biotechnology applications, with no specific mention of alternative protein products or ingredients intended to substitute animal-derived foods. | H12: =TRUE() -> TRUE | I12: CC | J12: NA | K12: =FALSE() -> FALSE | L12: =FALSE() -> FALSE | M12: =FALSE() -> FALSE | N12: =FALSE() -> FALSE | O12: =FALSE() -> FALSE | P12: ok
A13: grant.15078549 | B13: SEAlgaePower － Sustainable development of microalgae-based ingredients using waste streams from aquaculture and seafood processing industry as feedstock | C13: The overall objective of the SEAlgaePower project is to develop innovative microalgae-based technologies to clean wastewater from the aquaculture and seafood processing industry while simultaneously producing biomass for novel ingredients in a sustainable way. The specific aims are to: (i) select suitable microalgae species from the North and the Mediterranean Sea in a lab-scale cultivation system based on the ability to grow in different wastewater types; (ii) develop protocols for pilot-scale algae cultivation and wastewater cleaning; (iii) develop biorefinery protocols for protein, lipid and carbohydrate recovery from the microalgal biomass; (iv) develop microalgae-based product prototypes and ingredients; (v) assess environmental and socio-economic aspects associated with the project solutions for wastewater cleaning, microalgae cultivation and biomass valorisation, and (v) maximise the project impact, visibility, and legacy. In this project, UGOT will employ a two-stage cultivation in lab-scale for screening of microalgae growth in wastewater from salmon aquaculture and process waters from the seafood industry. Chalmers will analyse the biochemical composition of the various water types and will also contribute to biorefining of microalgal biomass by extracting protein for development of alternative food protein ingredients. RISE will use polysaccharide-enriched fractions from the biorefinery to develop fibre prototypes for use in wound care and regenerative medicine. | D13: in | E13: in | F13: 5 | G13: The project explicitly aims to extract protein from microalgal biomass for development of alternative food protein ingredients, which falls under fermentation/biomass fermentation scope, though the project also includes out-of-scope elements such as wastewater treatment, aquafeed, and medical applications (wound care, regenerative medicine). | H13: =TRUE() -> TRUE | I13: F | J13: F | K13: =TRUE() -> TRUE | L13: =FALSE() -> FALSE | M13: =TRUE() -> TRUE | N13: =FALSE() -> FALSE | O13: =FALSE() -> FALSE | P13: ok
A14: grant.15201530 | B14: 24BBR: Integrated bioinformatics resources for fungal and oomycetes pathogens of plants | C14: The spread of fungal and oomycete species presents significant challenges for current and future efforts in global food security, and threatens important non-food plant species in the UK ecosystem. Monoculture farming, changing climate and international trade are driving phytopathogen expansion into new geographical regions and new hosts. Discovery and translational research is increasingly reliant on genomic and other large-scale technologies, for example to identify genes implicated in invasion, pathogenesis, and plant responses/immunity. Genomes, population diversity data, and genomic-scale gene/protein expression datasets are now available in archival repositories for many phytopathogens, but, these static repositories do not support robust updating, querying and data-mining, making them difficult to exploit even by groups with extensive bioinformatics expertise. Our teams are responsible for the development and dissemination of two major international genome database resources: Ensembl and VEuPathDB (the Eukaryotic Pathogen, Vector and Host Knowledgebase) – both recognized as Global Core Biodata and Core Elixir Data resources, reflecting their international importance. Ensembl subsites relevant to plant health include Ensembl Fungi, Ensembl Protists (including oomycetes) and Ensembl Plants. Key features include a powerful, customisable genome browser supporting community tracks, phylogenetic gene trees displaying ortholog and paralog relationships across taxa, and visualisation of synteny, driven by whole genome alignments. Ensembl also provides production-grade genome annotation and transcriptome analysis, used in-house and integrated into the VEuPathDB pipeline to maximise efficiency and consistency, and minimise duplication of effort. VEuPathDB includes subsites focussed on infectious disease pathogens, including human and animal diseases prioritised by past/current funders, but also including plant pathogens with extensive functional data. The FungiDB component supports hundreds of species, including scores of important plant pathogens (Blumeria, Botrytis, Colletotrichum, Fusarium, Magnaporthe, Melampsora, Phytophthora, Puccinia, Ustilago, Zymoseptoria, etc) as well as taxa important in the food production and biotech sectors. In addition to gene/genome browsers, this knowledgebase provides powerful web-based tools and APIs for data integration and exploration, enabling users to ask their own questions in silico, seeking (for example) plant pathogen effectors based on protein motifs, gene/protein expression timing, signatures of selection and epigenetic marks, gene set enrichment, and leveraging orthology for cross-species functional inference based on phenotypic information. The HostDB component supports simultaneous interrogation of combined host-pathogen datasets. These proven, cost-effective resources have coordinated efforts for years, but have not previously benefited from dedicated funding to focus on phytopathogens. We propose to: Load or update 80+ genomes from archival repositories, using Ensembl annotation pipelines to build new or improve gene annotations, and the Apollo interface to capture expert knowledge from the community. Generate orthology mappings across taxa, protein domain annotations for all genomes, and further develop/deploy fungal-specific annotation tools focused on virulence factors, biosynthetic gene clusters and, protein structure-driven discovery of new or updated functions. Process/load 200+ functional genomic datasets and 30-40 plant response to infection datasets, enabling user-driven queries to identify genes of interest (e.g. for specific plant diseases), including support for analysis and visualisation of host-pathogen interactions (e.g. co-expression networks). Building on a history of successful collaboration and community engagement, outreach efforts will obtain community input on dataset prioritisation, and promote/explain effective use of informatics tools to advance research. FAIR data access is a priority; all datasets, tools and code will be fully open source and freely available through multiple routes (web browser, API, downloads) in support of plant health research. | D14: out | E14: out | F14: 1 | G14: This grant concerns bioinformatics database resources for fungal and oomycete plant pathogens to support plant health and food security research, with no connection to alternative protein development, production, or any related societal/environmental analysis. | H14: =TRUE() -> TRUE | I14: NA | J14: NA | K14: =TRUE() -> TRUE | L14: =FALSE() -> FALSE | M14: =FALSE() -> FALSE | N14: =FALSE() -> FALSE | O14: =FALSE() -> FALSE | P14: ok
A15: grant.15195928 | B15: 3D Bioprinting of cultivated meat: Biopolymer matrices supporting formation of muscle fibers in vitro | C15: Due to disruptive effects of conventional mass meat production – on climate, animals and human health, I work towards sustainable food for the next generation while maintaining taste, protein content and texture of real meat. Combining natural food ingredients, cells and tunable recombinant proteins, we may be able to grow whole beef cuts under controlled, animal-free conditions; innovative bioprinting techniques allow scale-up and nutrient supply in larger tissues. By adjusting the protein composition, I define the formation of edible muscle fibers. Improving the quality of cellular agriculture accelerates development of products with a real-world impact. | D15: in | E15: in | F15: 7 | G15: This grant explicitly focuses on cultivated meat, including scaffolding/biopolymer matrices, bioprinting techniques, and in vitro muscle fiber formation for growing beef cuts under animal-free conditions. | H15: =TRUE() -> TRUE | I15: CM | J15: CM | K15: =TRUE() -> TRUE | L15: =FALSE() -> FALSE | M15: =FALSE() -> FALSE | N15: =TRUE() -> TRUE | O15: =FALSE() -> FALSE | P15: ok
A16: grant.15051286 | B16: SEAlgaePower: Sustainable development of microalgae-based products using waste streams from aquaculture and seafood processing industry | C16: The fast-growing land-based aquaculture and seafood processing industry generate large amounts of nutrient-rich wastewater, posing a high cost for discharge and environmental impact. At the same time, there is an increasing demand for new resources intended for carbon-neutral production of food, material and energy. The ability of microalgae to perform photosynthesis and efficiently convert dissolved nutrients into valuable biomass could contribute to solving this dual problem. The overall objective of SEAlgaePower is to develop microalgae-based technologies to clean wastewater from the aquaculture and seafood processing industry while simultaneously producing biomass for novel ingredients in a sustainable way. The specific aims are to: (i) select suitable microalgae species/strains from the North and the Mediterranean Sea in a lab-scale cultivation system based on the ability to grow in different wastewater types; ((ii) develop pilot-scale algae cultivation protocols and wastewater cleaning; (iii) develop biorefinery protocols for protein, lipid and carbohydrate recovery from the microalgal biomass; (iv) develop microalgae-based prototypes and ingredients; (v) assess environmental and socio-economic aspects associated with the project solutions on wastewater cleaning, microalgae cultivation and biomass valorisation, and (v) maximise the project impact, visibility, and legacy. The SEAlgaePower consortium, coordinated by the University of Gothenburg, consists of thirteen partners from seven countries: Chalmers University of Technology, NORCE Norwegian Research Centre, University of Aveiro, University of Palermo, Sustainable Innovation Technology Services, RISE Research Institutes of Sweden, Nordicflexhouse, Danish Technological Institute, Universidade de Sao Paulo, Norwegian Institute of Bioeconomy Research, Klädesholmen Seafood, and RAGN-SELLS HAVBRUK. | D16: in | E16: in | F16: 5 | G16: The project develops microalgae biomass as a source of protein, lipid, and carbohydrate ingredients for novel food products, which falls under biomass fermentation/microalgae as an alternative protein source, though the application to alternative proteins specifically is implied rather than explicitly stated and the project also covers non-food applications (materials, energy, wastewater treatment). | H16: =TRUE() -> TRUE | I16: PB | J16: F | K16: =FALSE() -> FALSE | L16: =FALSE() -> FALSE | M16: =TRUE() -> TRUE | N16: =FALSE() -> FALSE | O16: =FALSE() -> FALSE | P16: ok
A17: grant.14881068 | B17: Expanding the CRISPR Toolbox for Engineering Synthetic Oscillators in Bacteria | C17: Synthetic biology offers innovative solutions to pressing global challenges such as climate change, food security, environmental degradation, and public health crises. Synthetic gene regulatory networks play a key role in harnessing the power of engineered biological systems. However, the inherent constraints of commonly used transcription factors, such the burden they place on the host metabolism, insufficient orthogonality, modularity and programmability, limit progress in engineering complex synthetic circuits for precise and programmable control of gene expression. CRISPR (clustered regularly interspaced short palindromic repeats)-based synthetic circuits, where interactions between different network nodes are implemented with CRISPR interference (CRISPRi) and CRISPR activation (CRISPRa), circumvent some of those shortcomings and make circuit design more modular and scalable. Despite the enormous potential, research on how to engineer such circuits in bacteria is still at its beginning. I propose to further improve the toolbox of bacterial CRISPR-based dynamic synthetic circuits and to apply it to build CRISPR-based synthetic oscillators in Escherichia coli. Oscillatory circuits exhibit periodic fluctuations in gene expression and are pervasive in living organisms, with examples in cell cycles, circadian rhythms, metabolic activities, and pattern formation during multicellular development. Diverse applications of synthetic oscillators have already been proposed, ranging from fundamental research, bioproduction, biological computing and therapeutic applications to biological timers.We will establish a collection of synthetic CRISPRi-based oscillators with different Cas proteins and circuit topologies. The collection will span oscillators differing in their properties, such as amplitude, frequency, and accuracy. We will also go beyond the-state-of-the-art in integrating CRISPRi and CRISPRa in the same circuit. Finally, we will assess and if necessary, improve the evolutionary stability of the built CRISPR-based oscillators. To reach our objectives, we will apply a combination of experimental approaches (including optogenetics, microfluidics, and evolutionary experiments) and computational modelling.Our work will be at the forefront of synthetic biology by developing novel CRISPRi/a systems, applying them to synthetic oscillators and enabling the combination of multiple circuits within a single cell. Ensuring the stability of our circuits will enhance their future applications in fields as diverse as biotechnology, medicine, biological sensors, engineered living materials and biocomputing. The results of this project are also highly relevant to developmental biology, where temporal oscillations play a critical role in pattern formation during embryonic development. In summary, this project holds potential to unlock new possibilities in both fundamental biology and applied science. | D17: out | E17: out | F17: 1 | G17: This grant concerns CRISPR-based synthetic gene regulatory circuits and oscillators in bacteria for general synthetic biology applications, with no connection to alternative protein production or any alternative protein product. | H17: =TRUE() -> TRUE | I17: NA | J17: NA | K17: =TRUE() -> TRUE | L17: =FALSE() -> FALSE | M17: =FALSE() -> FALSE | N17: =FALSE() -> FALSE | O17: =FALSE() -> FALSE | P17: ok
A18: grant.14950468 | B18: Mechanisms of enoyl reductase recruitment and iterative module suppression in trans-acyltransferase polyketide synthases | C18: Bacteria are remarkable chemists capable of assembling complex molecules that enter cells and bind biomolecular targets with high affinity and selectivity. Consequently, bacterial natural products have wide-ranging applications in medicine (as antibiotics, anticancer agents, and immunomodulators) and agriculture (as insecticides, fungicides, and herbicides). How the "blind watchmaker" of evolution creates structurally diverse molecular architectures is a key question in contemporary biosynthesis research. In this proposal, we seek to illuminate how enoylreductase (ER) enzymes contribute to structural diversification of an important class of bacterial natural products called polyketides by understanding how trans-acting ERs are recruited to and suppress iteration in specific modules of trans-acyltransferase (trans-AT) polyketide synthases (PKSs). The specific objectives of our proposal are: Establish the structural basis for productive interaction between trans-acting ERs and specific acyl carrier protein domains in trans-AT PKSs. Elucidate the substrate tolerance and catalytic mechanism of trans-acting ERs involved in the assembly of the antibiotic gladiolin and the anticancer agent gladiostatin. Investigate the generality and molecular mechanism for suppression of trans-AT PKS module iteration by trans-acting ERs. The knowledge gained from this interdisciplinary research will enable the development of bioengineering approaches to alter the degree of unsaturation and chain length of polyketide natural products, which often require structural modification to optimise them for therapeutic or agricultural application. Structural modification of polyketides using synthetic chemistry is challenging due to their complexity. Moreover, such methods rely on non-renewable petrochemical feedstocks, are energy intensive, create environmentally damaging byproducts, and are expensive. In contrast, structural modification of polyketides via bioengineering enables optimised derivatives to be produced via fermentation, which is cheaper, more energy efficient, has lower environmental impact, and utilises sustainable plant-derived feedstocks. This research is directly relevant to the Engineering Biology theme of BBSRC's Transformative Technologies priority of the Advancing the Frontiers of Bioscience Discovery high level objective. It also aligns with the Sustainable Agricultural Systems focus area of the Bioscience for Sustainable Agriculture and Food priority, the Production of More Sustainable Products focus area of the Bioscience for Advanced Manufacturing and Clean Growth priority, and the Combatting Antimicrobial Resistance research priority of the Bioscience for an Integrated Understanding of Health priority of BBSRC's Tackling Strategic Challenges high level objective. | D18: out | E18: out | F18: 1 | G18: This grant concerns fundamental biochemistry of polyketide synthases for antibiotic and anticancer agent development, with no connection to alternative proteins or animal product substitution. | H18: =TRUE() -> TRUE | I18: NA | J18: NA | K18: =TRUE() -> TRUE | L18: =FALSE() -> FALSE | M18: =FALSE() -> FALSE | N18: =FALSE() -> FALSE | O18: =FALSE() -> FALSE | P18: ok
A19: grant.14959694 | B19: Samenwerking tussen methanotrofen en sulfide oxiderende bacteriën om uit biogas hoogwaardig eiwitrijk aquacultuur voeder te produceren. | C19: Duurzame voedselvoorziening voor de groeiende wereldbevolking is een belangrijke uitdaging in de 21e eeuw. Aquacultuur kan hierin een centrale rol spelen, maar gebruikt momenteel vismeel en andere dierlijke eiwitten als voeder om een eiwitrijk product te genereren met alle essentiële aminozuren voor de mens. Er is dus nood aan de ontwikkeling van nieuwe, duurzame voedingsbronnen uit herwonnen, hernieuwbare grondstoffen. Hier zullen we biogas gebruiken, geproduceerd uit afval van recirculerende aquacultuursystemen, om hoogwaardige microbiële eiwitten te produceren. We zullen een nieuw consortium creëren van methaan-oxiderende (MOB) en sulfide-oxiderende (SOB) bacteriën die rijk zijn aan alle essentiële aminozuren. Eerst zullen we MOB combineren met SOB door (1) het individueel en samen opgroeien van pure MOB- en SOB-culturen en (2) het (samen) aanrijken van de SOB en MOB. Vervolgens zullen de meest optimale MOB-SOB-partnerschappen, op basis van het essentieel aminozuurgehalte, worden gebruikt om nieuwe macrostructuren of “biovlokken” te creëren. Vervolgens zullen we deze MOB-SOB microbiële biomassa gebruiken als voeder voor Artemia. Ten slotte zullen we de MOB-SOB-biomassa direct (als biovlokken) en indirect (als Artemia gekweekt op MOB-SOB-biomassa) gebruiken als voeder om garnalen te kweken tot een voedselbron, rijk aan alle essentiële aminozuren. De hier gegenereerde kennis zal het mogelijk maken om naar circulariteit in de aquacultuur te evolueren. | D19: out | E19: out | F19: 2 | G19: This grant concerns the production of microbial protein (from methanotrophs and sulfide-oxidizing bacteria) as aquafeed for shrimp and Artemia aquaculture, not as a substitute for animal-derived foods for human consumption, placing it outside the scope of alternative proteins for human food. | H19: =TRUE() -> TRUE | I19: NA | J19: NA | K19: =TRUE() -> TRUE | L19: =FALSE() -> FALSE | M19: =FALSE() -> FALSE | N19: =FALSE() -> FALSE | O19: =FALSE() -> FALSE | P19: ok
A20: grant.14955094 | B20: Demonstrating a cost competitive, sustainable, scalable intensified micro-algae bioprocess for the production of food-grade medium value, carbon negative Ingredients exceeding Market Standards | C20: Micro-Algae offer a solution to many of the European bioeconomy needs. Nevertheless, significant challenges still exist to their acceptance on the market, including organoleptic and functionality challenges. CleanAlgae2Value seeks to unlock such potential via a cascading approach to white-microalgae-derived medium-price ingredients, including protein isolates, oils, natural pigments and starch. The project will build and operate a replicable “upgrading-module” to drastically enhance relevant biorefineries performance via a cost-competitive, sustainable, and scalable microalgae fractionation and valorisation process for producing food-grade, medium-value, carbon-negative ingredients that exceed market standards. More specifically, the project will prove the effectiveness and efficiency of a “Micro-Algae Biorefinery Upgrade Module” (MABUM), able to unlock productions of protein isolates, protein concentrates, starch-rich fraction and oils (respectively 2, 1.3, 3.98 and 1.8 tons) to be validated into 15 prototypes, 13 for food and 2 for bio-packaging markets. The project will do so while increasing operative margins, by decreasing “value-normalised” CAPEX and OPEX, also thanks to modelling optimisation, contributing to market penetration. Importantly, CleanAlgae2Value would also benefit from synergies with a recently granted EIC Accelerator project, which focuses on upstream algae production from CO2 via SOL two-step fermentation, using solely CO2 as carbon source. The project brings together 16 organizations from 9 European countries, collaborating with end-users to produce added value ingredients. Holistic evaluations, including both empirical (surveys, workshops) and horizontal considerations (LCA, TEA, SSbD), will allow for the assessment of market acceptance and environmental, economic and societal sustainability, as well as further support and boost the project DCE activities and pathways towards EFSA positive opinion for those ingredients that still require it. | D20: in | E20: in | F20: 6 | G20: The grant focuses on microalgae biorefinery processes to produce protein isolates and concentrates as food-grade ingredients, which falls under fermentation/biomass fermentation (microalgae as a protein source), with explicit food applications and LCA/TEA assessments relevant to alternative proteins. | H20: =TRUE() -> TRUE | I20: PB | J20: F | K20: =FALSE() -> FALSE | L20: =FALSE() -> FALSE | M20: =TRUE() -> TRUE | N20: =FALSE() -> FALSE | O20: =FALSE() -> FALSE | P20: ok
A21: grant.15196386 | B21: OPTIPRO: Optimizing protein production in Bacillus | C21: Bacillus species are widely used for the industrial-scale production of enzymes used in e.g. washing powders, food and agricultural applications and in the pharmaceutical and biotechnological industry. However, the range of enzymes that are secreted at high-levels by these bacteria is currently limited. The University of Amsterdam, VU University, and 4 biotech firms are collaborating to address this problem by combining deep sequencing-based transposon mutagenesis with novel high-throughput single cell selection techniques to improve the production of a diverse set of commercially relevant enzymes. This project will provide valuable knowledge to optimize enzyme secretion in Bacillus species, and other microbial production platforms. | D21: out | E21: out | F21: 1 | G21: This grant focuses on optimizing enzyme secretion in Bacillus species for industrial applications (washing powders, pharmaceuticals, agriculture), with no stated application in alternative protein production or substitution of animal-derived foods. | H21: =TRUE() -> TRUE | I21: NA | J21: NA | K21: =TRUE() -> TRUE | L21: =FALSE() -> FALSE | M21: =FALSE() -> FALSE | N21: =FALSE() -> FALSE | O21: =FALSE() -> FALSE | P21: ok
A22: grant.14751838 | B22: Secondary treatment of RAS water and nutrient revalorization by site-specific microbial biofilm | C22: Rising demand for nutritious fish and seafood, coupled with declining wild catches, has made aquaculture the fastest growing sector in food production. Two of the largest current bottlenecks for sustainable increased production of farmed fish are 1) identifying alternative and sustainable sources of protein and fatty acids for fish feed, and 2) finding new solutions for sustainable treatment of side streams in recirculating aquaculture systems (RAS). To steer away from current unsustainable practices innovative and sustainable ideas focusing on re-valorisation and bio-circularity needs to be implemented. In this project we propose the integration of a microalgal reactor as a modular process unit that can be included in RAS facilities, to upcycle side streams from the fish farming and generate a valuable biomass that can be valorized in the agri-food sector. In the module we will growth a naturally selected, benthic biofilm community arising from a mixture of organisms already present in the nitrogen (N)-rich RAS water of the facility. This benthic community, native to the RAS water, can effectively capture nutrients in the water phase. With an interdisciplinary team of chemist, biologist, engeeniers and modellers we plan to build and run pilots at two industrial RAS sites and evaluate the production yield and the composition of recovered microalgal biomass for different end-uses. We will explore where this system can be integrated in the process scheme of a RAS facility and evaluate the footprint and costs connected to running it. Once harvested the biomass will be evaluated for suitability as a feed ingredient (for chicken or salmon) or directly as food for snails. Biggest challenges this project will help solve are related to the high costs of productivity, feasibility of integration of the system in a RAS facility, evaluation the environmental footprint and reproducibility/consistency of recovered biomass between different farms. | D22: out | E22: out | F22: 2 | G22: This grant focuses on microalgal biofilm for treating aquaculture wastewater and producing biomass for animal feed (chicken, salmon) or snail food, not for human alternative protein products. | H22: =TRUE() -> TRUE | I22: NA | J22: NA | K22: =TRUE() -> TRUE | L22: =FALSE() -> FALSE | M22: =FALSE() -> FALSE | N22: =FALSE() -> FALSE | O22: =FALSE() -> FALSE | P22: ok
