Workbook

Sheet Dimensions combined
A1: Source | B1: Rank | C1: Grant ID | D1: duplicate check on grant ID | E1: return ID to check | F1: duplicate check with new airtabe entries | G1: return ID to check | H1: Grant Number(s) | I1: Title | J1: Title translated | K1: Abstract | L1: Abstract translated | M1: AI Scope check? | N1: Technology Pillar | O1: Research Category | P1: Keywords | Q1: Funding amount | R1: Currency | S1: Funding amount in USD | T1: Start date | U1: Start Year | V1: End Date | W1: End Year | X1: Researchers | Y1: Research Organization - original | Z1: Research Organization - standardized | AA1: GRID ID | AB1: City of standardized research organization | AC1: State of standardized research organization | AD1: Country of standardized research organization | AE1: Funder | AF1: Funder Group | AG1: Funder Country | AH1: Program | AI1: NIH activity code | AJ1: Resulting publications | AK1: Source Linkout | AL1: Dimensions URL | AM1: Fields of Research (ANZSRC 2020) | AN1: RCDC Categories | AO1: HRCS HC Categories | AP1: HRCS RAC Categories | AQ1: Health Research Areas | AR1: Broad Research Areas | AS1: Cancer Types | AT1: CSO Categories | AU1: Units of Assessment | AV1: Sustainable Development Goals
A2: 2025 Dimensions CM | B2: 1500 | C2: grant.15195353 | D2: =ISNUMBER(MATCH(C2, 'Airtable copy'!N:N, 0)) -> FALSE | E2: =VLOOKUP(C2,'Airtable copy'!N:N,1,FALSE) -> #REF! | F2: =ISNUMBER(MATCH(C2, 'Grants tracker download'!O:O, 0)) -> FALSE | G2: =VLOOKUP(C2,'Grants tracker download'!O:O,1,FALSE) -> #REF! | H2: 22740 | I2: Epigenetic Reprogramming for Cellular Agriculture (EPICA) | J2: Epigenetic Reprogramming for Cellular Agriculture (EPICA) | K2: Cellular agriculture has the potential to revolutionise protein production by offering sustainable and ethical alternatives to traditional animal farming. However, many challenges currently limit its commercial viability, including a critical lack of flexible, regulatory- and consumer-friendly technologies to engineer cell lines for large-scale production. EPICA (Epigenetic Reprogramming for Cellular Agriculture) will pioneer the use of epigenetic editing to enhance a variety of critical cell characteristics without genetic modification. We will build a toolkit for engineering of multiple cell types from different species, and demonstrate its use in industrial-scale cultivated meat and seafood bioprocesses, helping bring these technologies to market. | L2: Cellular agriculture has the potential to revolutionise protein production by offering sustainable and ethical alternatives to traditional animal farming. However, many challenges currently limit its commercial viability, including a critical lack of flexible, regulatory- and consumer-friendly technologies to engineer cell lines for large-scale production. EPICA (Epigenetic Reprogramming for Cellular Agriculture) will pioneer the use of epigenetic editing to enhance a variety of critical cell characteristics without genetic modification. We will build a toolkit for engineering of multiple cell types from different species, and demonstrate its use in industrial-scale cultivated meat and seafood bioprocesses, helping bring these technologies to market. | M2: Yes | N2: Cultivated | O2: Cell line development | Q2: 904867 | R2: EUR | S2: 960340 | T2: 2025-01-01 | U2: 2025 | X2: Joshua Flack, Marcel Ottens, Marianne Rots | Y2: Technische Universiteit Delft; Universitair Medisch Centrum Groningen | Z2: Delft University of Technology; University Medical Center Groningen | AA2: grid.5292.c; grid.4494.d | AB2: Delft; Groningen | AC2: Zuid-Holland; Groningen | AD2: Netherlands; Netherlands | AE2: Dutch Research Council | AF2: cOAlition S | AG2: Netherlands | AH2: Open technologieprogramma OTP 2025 2025-3 (Funding Scheme) | AI2: Not available | AL2: https://app.dimensions.ai/details/grant/grant.15195353 | AM2: 31 Biological Sciences; 3105 Genetics | AN2: Genetics | AO2: Generic health relevance | AU2: A01 Clinical Medicine | AV2: 2 Zero Hunger
A3: 2025 Dimensions CM | B3: 1395 | C3: grant.15195928 | D3: =ISNUMBER(MATCH(C3, 'Airtable copy'!N:N, 0)) -> FALSE | E3: =VLOOKUP(C3,'Airtable copy'!N:N,1,FALSE) -> #REF! | F3: =ISNUMBER(MATCH(C3, 'Grants tracker download'!O:O, 0)) -> FALSE | G3: =VLOOKUP(C3,'Grants tracker download'!O:O,1,FALSE) -> #REF! | H3: 10.61686/VFIVD43947; 21927 | I3: 3D Bioprinting of cultivated meat: Biopolymer matrices supporting formation of muscle fibers in vitro | J3: 3D Bioprinting of cultivated meat: Biopolymer matrices supporting formation of muscle fibers in vitro | K3: Due to disruptive effects of conventional mass meat production – on climate, animals and human health, I work towards sustainable food for the next generation while maintaining taste, protein content and texture of real meat. Combining natural food ingredients, cells and tunable recombinant proteins, we may be able to grow whole beef cuts under controlled, animal-free conditions; innovative bioprinting techniques allow scale-up and nutrient supply in larger tissues. By adjusting the protein composition, I define the formation of edible muscle fibers. Improving the quality of cellular agriculture accelerates development of products with a real-world impact. | L3: Due to disruptive effects of conventional mass meat production – on climate, animals and human health, I work towards sustainable food for the next generation while maintaining taste, protein content and texture of real meat. Combining natural food ingredients, cells and tunable recombinant proteins, we may be able to grow whole beef cuts under controlled, animal-free conditions; innovative bioprinting techniques allow scale-up and nutrient supply in larger tissues. By adjusting the protein composition, I define the formation of edible muscle fibers. Improving the quality of cellular agriculture accelerates development of products with a real-world impact. | M3: Yes | N3: Cultivated | O3: Scaffolding & Texturisation | Q3: 320000 | R3: EUR | S3: 339617 | T3: 2025-10-01 | U3: 2025 | X3: David Kilian | Y3: Maastricht University | Z3: Maastricht University | AA3: grid.5012.6 | AB3: Maastricht | AC3: Limburg | AD3: Netherlands | AE3: Dutch Research Council | AF3: cOAlition S | AG3: Netherlands | AH3: NWO-Talentprogramma Veni TTW 2024 (Funding Scheme) | AI3: Not available | AK3: https://doi.org/10.61686/VFIVD43947 | AL3: https://app.dimensions.ai/details/grant/grant.15195928 | AM3: 30 Agricultural, Veterinary and Food Sciences; 3003 Animal Production; 31 Biological Sciences | AN3: Biotechnology; Nutrition | AQ3: Biomedical | AR3: Basic Science | AU3: A06 Agriculture, Veterinary and Food Science | AV3: 2 Zero Hunger
A4: 2025 Dimensions CM | B4: 1328 | C4: grant.15156031 | D4: =ISNUMBER(MATCH(C4, 'Airtable copy'!N:N, 0)) -> FALSE | E4: =VLOOKUP(C4,'Airtable copy'!N:N,1,FALSE) -> #REF! | F4: =ISNUMBER(MATCH(C4, 'Grants tracker download'!O:O, 0)) -> FALSE | G4: =VLOOKUP(C4,'Grants tracker download'!O:O,1,FALSE) -> #REF! | H4: 565625683 | I4: Engineered bionanoparticles as carriers for growth factors and peptides that promote cell attachment, proliferation and differentiation to improve the production of low-cost cultured meat (NanoMeat) | J4: Engineered bionanoparticles as carriers for growth factors and peptides that promote cell attachment, proliferation and differentiation to improve the production of low-cost cultured meat (NanoMeat) | K4: Cultured or artificial meat is a form of cellular agriculture involving the production of meat from animal cells cultivated in vitro. This rapidly developing technology could provide meat to the world’s growing population while also addressing the drawbacks of traditional livestock agriculture, such as infectious diseases, antibiotic misuse, poor animal welfare, and greenhouse gas emissions. To become competitive, cultured meat must be economically comparable and ethically superior to natural meat, but this is challenging because fetal bovine serum (FBS) is needed in the culture medium to provide growth factors for cell proliferation and differentiation. FBS is expensive and can only be sourced by killing calves. A more cost-effective and ethical solution is the use of scaffolds for recombinant growth factors, offering the advantages of controlled release, greater efficacy and lower costs. Growth factors can be immobilized on plant virus-like nanoparticles (VNPs/VLPs), which are versatile and biocompatible scaffolds that act as protein-based carriers. VNPs/VLPs can be incorporated as hydrogel composites to enhance stem cell adhesion and promote cell differentiation in a 3D environment. Plant VNPs/VLPs are well tolerated by mammals and are neither toxic nor infectious to mammalian cells in vitro, making them ideal for the production of cultured meat. The proposed project will address the following research questions: (1) Can stem cells be cultivated with engineered VNPs/VLPs displaying cell adhesion peptides and growth factors in a hydrogel matrix? (2) Do these scaffolds promote stem cell attachment, proliferation, differentiation and maturation? (3) Can these scaffolds replace FBS, thus providing a safe, inexpensive and ethical alternative for cultured meat production? | L4: Cultured or artificial meat is a form of cellular agriculture involving the production of meat from animal cells cultivated in vitro. This rapidly developing technology could provide meat to the world’s growing population while also addressing the drawbacks of traditional livestock agriculture, such as infectious diseases, antibiotic misuse, poor animal welfare, and greenhouse gas emissions. To become competitive, cultured meat must be economically comparable and ethically superior to natural meat, but this is challenging because fetal bovine serum (FBS) is needed in the culture medium to provide growth factors for cell proliferation and differentiation. FBS is expensive and can only be sourced by killing calves. A more cost-effective and ethical solution is the use of scaffolds for recombinant growth factors, offering the advantages of controlled release, greater efficacy and lower costs. Growth factors can be immobilized on plant virus-like nanoparticles (VNPs/VLPs), which are versatile and biocompatible scaffolds that act as protein-based carriers. VNPs/VLPs can be incorporated as hydrogel composites to enhance stem cell adhesion and promote cell differentiation in a 3D environment. Plant VNPs/VLPs are well tolerated by mammals and are neither toxic nor infectious to mammalian cells in vitro, making them ideal for the production of cultured meat. The proposed project will address the following research questions: (1) Can stem cells be cultivated with engineered VNPs/VLPs displaying cell adhesion peptides and growth factors in a hydrogel matrix? (2) Do these scaffolds promote stem cell attachment, proliferation, differentiation and maturation? (3) Can these scaffolds replace FBS, thus providing a safe, inexpensive and ethical alternative for cultured meat production? | M4: Yes | N4: Cultivated | O4: Cell culture media | Q4: 0 | S4: 0 | T4: 2025-01-01 | U4: 2025 | X4: Che Julius Ngwa, Juliane Schuphan | Y4: Fraunhofer-Institut für Molekularbiologie und Angewandte Oekologie; Rheinisch-Westfälische Technische Hochschule Aachen | Z4: Fraunhofer Institute for Molecular Biology and Applied Ecology; RWTH Aachen University | AA4: grid.418010.c; grid.1957.a | AB4: Schmallenberg; Aachen | AC4: Nordrhein-Westfalen | AD4: Germany; Germany | AE4: Deutsche Forschungsgemeinschaft | AG4: Germany | AH4: Research Grants (DFG Programme) | AI4: Not available | AK4: https://gepris.dfg.de/gepris/projekt/565625683?language=en | AL4: https://app.dimensions.ai/details/grant/grant.15156031 | AM4: 30 Agricultural, Veterinary and Food Sciences; 3003 Animal Production; 31 Biological Sciences; 40 Engineering; 4003 Biomedical Engineering | AN4: Bioengineering; Biotechnology; Nanotechnology; Regenerative Medicine; Stem Cell Research; Stem Cell Research - Nonembryonic - Human; Stem Cell Research - Nonembryonic - Non-Human | AP4: 5.2 Cellular and gene therapies | AQ4: Biomedical | AR4: Basic Science | AU4: A05 Biological Sciences | AV4: 3 Good Health and Well Being
A5: 2025 Dimensions CM | B5: 1301 | C5: grant.14972651 | D5: =ISNUMBER(MATCH(C5, 'Airtable copy'!N:N, 0)) -> FALSE | E5: =VLOOKUP(C5,'Airtable copy'!N:N,1,FALSE) -> #REF! | F5: =ISNUMBER(MATCH(C5, 'Grants tracker download'!O:O, 0)) -> FALSE | G5: =VLOOKUP(C5,'Grants tracker download'!O:O,1,FALSE) -> #REF! | H5: 359609 | I5: Cell-cultured octopus production through sustainable marine biomass valorization | J5: Cell-cultured octopus production through sustainable marine biomass valorization | K5: SEANERGIES aims to develop the scientific and technological foundation for producing cultivated octopus—meat grown from cells without killing animals. As global demand for protein rises, traditional fishing and aquaculture face major challenges, including overfishing, pollution, and animal welfare concerns. Octopuses are especially vulnerable, yet they are also highly valued for their nutrition and cultural significance. The project uses an interdisciplinary approach combining marine biology, bioengineering, and social sciences. It will explore the octopus’s natural ability to regenerate muscle tissue to create the first stable octopus muscle cell line for use in cellular agriculture. To make this process sustainable and animal-free, SEANERGIES will develop innovative culture media based on microalgae and natural scaffolds from seaweed (Saccharina latissima, NORWEGIAN Partner's Role), providing the structure needed for muscle growth. Key R&D challenges include isolating and growing octopus cells long-term, replacing animal-derived nutrients in cell culture, and ensuring that marine-based materials can support cell attachment and development. The project will also assess the environmental and social impacts of cultivated seafood in Portugal, Italy, and Brazil. SEANERGIES contributes to global food security and ocean health by offering a sustainable alternative to traditional seafood, aligned with EU Green Deal goals and the UN Sustainable Development Goals. | L5: SEANERGIES aims to develop the scientific and technological foundation for producing cultivated octopus—meat grown from cells without killing animals. As global demand for protein rises, traditional fishing and aquaculture face major challenges, including overfishing, pollution, and animal welfare concerns. Octopuses are especially vulnerable, yet they are also highly valued for their nutrition and cultural significance. The project uses an interdisciplinary approach combining marine biology, bioengineering, and social sciences. It will explore the octopus’s natural ability to regenerate muscle tissue to create the first stable octopus muscle cell line for use in cellular agriculture. To make this process sustainable and animal-free, SEANERGIES will develop innovative culture media based on microalgae and natural scaffolds from seaweed (Saccharina latissima, NORWEGIAN Partner's Role), providing the structure needed for muscle growth. Key R&D challenges include isolating and growing octopus cells long-term, replacing animal-derived nutrients in cell culture, and ensuring that marine-based materials can support cell attachment and development. The project will also assess the environmental and social impacts of cultivated seafood in Portugal, Italy, and Brazil. SEANERGIES contributes to global food security and ocean health by offering a sustainable alternative to traditional seafood, aligned with EU Green Deal goals and the UN Sustainable Development Goals. | M5: Yes | N5: Cultivated | O5: Cell line development / Media | Q5: 2891999 | R5: NOK | S5: 262375 | T5: 2025-01-01 | U5: 2025 | V5: 2028-12-31 | W5: 2028 | X5: Alexander Jüterbock | Y5: NORD UNIVERSITET | Z5: Nord University | AA5: grid.465487.c | AB5: Bodø | AD5: Norway | AE5: The Research Council of Norway | AF5: cOAlition S | AG5: Norway | AH5: SEA-BASED-SEA-BASED (Funding scheme) | AI5: Not available | AK5: https://prosjektbanken.forskningsradet.no/en/project/FORISS/359609 | AL5: https://app.dimensions.ai/details/grant/grant.14972651 | AM5: 31 Biological Sciences; 41 Environmental Sciences; 4104 Environmental Management; 48 Law and Legal Studies; 4803 International and Comparative Law | AO5: Generic health relevance | AU5: B07 Earth Systems and Environmental Sciences | AV5: 14 Life Below Water; 2 Zero Hunger
A6: 2025 Dimensions CM | B6: 493 | C6: grant.14970420 | D6: =ISNUMBER(MATCH(C6, 'Airtable copy'!N:N, 0)) -> FALSE | E6: =VLOOKUP(C6,'Airtable copy'!N:N,1,FALSE) -> #REF! | F6: =ISNUMBER(MATCH(C6, 'Grants tracker download'!O:O, 0)) -> FALSE | G6: =VLOOKUP(C6,'Grants tracker download'!O:O,1,FALSE) -> #REF! | I6: BiochAIn - BiochAIn ist ein Softwareprojekt für die Optimierung einer gesamten biotechnologischen Verfahrenskette(Chain) mittels AI | J6: BiochAIn - BiochAIn is a software project for optimizing an entire biotechnological process chain using AI | K6: Biotechnologische Produktionsverfahren finden breite Anwendung in der pharmazeutischen Industrie, zur Herstellung von Feinchemikalien, in der Umwelttechnologie und in der Lebensmittelindustrie und generieren eine hohe Wertschöpfung. Aufgrund der hohen Komplexität dieser Verfahren, bedingt durch das vielschichtige Zusammenspiel von Biologie und Verfahrenstechnik, besteht in zahlreichen Fällen ein nur sehr eingeschränktes Prozessverständnis. Dies wiederum führt zu wenig effizienten und daher teuren Prozessen, limitiert die Möglichkeiten zur Prozessoptimierung und ist auch ein wesentlicher Grund dafür, dass bis dato die enormen Fortschritte im Bereich der Digitalisierung, Methoden der künstlichen Intelligenz und Modellierung/Simulation nicht im erforderlichen Ausmaß zur Auslegung und Führung von Bioprozessen zur Anwendung kommen. Im Rahmen des Projektes soll daher eine generische Software-Toolbox entwickelt werden um genannte Fortschritte im Bereich der Digitalisierung den Experten der Domäne Bioprozess-technik zugänglich machen und eine Implementierung der Digitalisierung gemäß Industrie 4.0 im Bio-Manufacturing ermöglichen. Mit dem BiochAIn Projekt hat sich die Novasign zum Ziel gesetzt, weltweit die erste digitale Prozessmodellierungstoolbox für die Optimierung aller biotechnologisch relevanten Verfahrensschritte zu entwickeln. Mit dieser Software-Suite soll es erstmals möglich werden, dass Biotechnologen und Bioprozessingenieur:innen über eine nutzerzentrierte grafische Bedienoberfläche alle Einzelschritte der Prozesskette, sowohl individuell als auch in ihrer Gesamtheit, mit Hilfe von Modellen und Simulation selbstständig und unabhängig von hochspezialisierten Softwareentwicklern und Data Scientists optimieren können. Die Software wird auch ermöglichen, dass Prozessingenieur:innen abteilungsübergreifend Herstellungsprozesse für Produkte (zum Beispiel einen Antikörper für die Krebstherapie) in einem integrativen Ansatz optimieren können um lebensrettende Medizin den Patient:innen früher und günstiger zur Verfügung stellen zu können. Die Softwareentwicklung wird in 4 Blöcke aufgeteilt und soll über einen Zeitraum von 4 Jahren (durch schnelleren Fortschritt verkürzt auf 3 Jahre) erfolgen. Im ersten Schritt wurde eine geeignete Softwarearchitektur festgelegt, welche einerseits alle technischen Herausforderungen bewältigen kann und andererseits für Benutzer:innen, einfach bedienbar ist. In einem Datenvorverarbeitungs-/Visualisierungsblock werden Onlinedaten (Prozesssystem) und Offlinedaten (Messungen) mit Methoden der statistischen Datenaufbereitung und Analyse vorprozessiert, verknüpft und so für Visualisierung und Modellierung vorbereitet. Der Modellierblock wird so aufgesetzt, dass die unterschiedlichsten State-of-the-art Machine Learning (ML) Methoden implementiert werden und so die jeweils bestgeeignete Methode für zur Modellierung unterschiedlicher Bioprozessschritte eingesetzt werden kann. Im finalen Schritt, dem digitalen Zwilling, kann jeder einzelne der Modellblöcke individuell oder mittels drag-and-drop mit anderen Einheiten verknüpft zu einer Prozesskette nach einer bestimmten Zielgröße (z.B. höchstmögliche Produktausbeute oder kürzere Prozessdauer) optimiert werden und für die online Monitoring angewendet werden. Um Nutzer:innen bestmöglich unterstützen zu können, wird die Software über eine selbstlernende Funktion (Artificial Intelligence) verfügen, welche es möglich macht, jeden einzelnen Verfahrensschritt als auch die gesamte Prozesskette schnell, zielgerichtet und automatisiert entlang eines Workflows zu optimieren. Die Software soll neben der biopharmazeutischen Industrie auch für die industrielle Biotechnologie (Herstellung von Enzymen und biobasierten Polymeren aus Abfallströmen) als auch im Bereich der Lebensmittelindustrie für die Erzeugung von Proteinersatzstoffen (Cultured Meat, Precision Fermentation) Verwendung finden. Der Name BiochAIn leitet sich daher aus Bio (für Bioprozess), chain (für Prozesskette) und AI (für die Künstliche Intelligenz der Selbstlernfunktion) ab. | L6: Biotechnological production processes are widely used in the pharmaceutical industry, for the production of fine chemicals, in environmental technology, and in the food industry, and generate high added value. Due to the high complexity of these processes, caused by the complex interplay of biology and process engineering, in many cases there is only a very limited understanding of the processes. This, in turn, leads to inefficient and therefore expensive processes, limits the possibilities for process optimization, and is also a key reason why the enormous advances in digitalization, artificial intelligence methods, and modeling/simulation have not yet been applied to the required extent for the design and management of bioprocesses. The project therefore aims to develop a generic software toolbox to make these advances in digitalization accessible to experts in the bioprocess engineering domain and enable the implementation of digitalization in accordance with Industry 4.0 in biomanufacturing. With the BiochAIn project, Novasign aims to develop the world's first digital process modeling toolbox for optimizing all biotechnologically relevant process steps. This software suite will enable biotechnologists and bioprocess engineers to independently optimize all individual steps of the process chain, both individually and as a whole, using models and simulations via a user-centered graphical user interface, independently of highly specialized software developers and data scientists. The software will also enable process engineers to optimize manufacturing processes for products (e.g., an antibody for cancer therapy) across departments using an integrative approach to make life-saving medicine available to patients sooner and more cost-effectively. Software development will be divided into four blocks and will be completed over a period of four years (shortened to three years due to faster progress). The first step involved defining a suitable software architecture that, on the one hand, can address all technical challenges and, on the other, is easy to use for users. In a data preprocessing/visualization block, online data (process system) and offline data (measurements) are preprocessed using statistical data processing and analysis methods, linked, and prepared for visualization and modeling. The modeling block is set up to implement a wide variety of state-of-the-art machine learning (ML) methods, allowing the most suitable method to be used for modeling different bioprocess steps. In the final step, the digital twin, each of the model blocks can be optimized individually or linked to other units via drag-and-drop to form a process chain according to a specific target (e.g., highest possible product yield or shorter process time) and applied for online monitoring. To provide the best possible support to users, the software will feature a self-learning function (artificial intelligence), which makes it possible to quickly, specifically, and automatically optimize each individual process step as well as the entire process chain along a workflow. In addition to the biopharmaceutical industry, the software is also intended to be used for industrial biotechnology (production of enzymes and bio-based polymers from waste streams) as well as in the food industry for the production of protein substitutes (cultured meat, precision fermentation). The name BiochAIn is therefore derived from Bio (for bioprocess), chain (for process chain), and AI (for the artificial intelligence of the self-learning function). | M6: Yes | N6: Cross-cutting | O6: Bioprocess design | Q6: 0 | S6: 0 | T6: 2025-01-04 | U6: 2025 | V6: 2026-03-31 | W6: 2026 | Y6: Novasign GmbH | AE6: Austrian Research Promotion Agency | AG6: Austria | AH6: IWI 24/26 (program); Basic Program Call for Proposals 2025 (program) | AI6: Not available | AK6: https://projekte.ffg.at/projekt/5139169 | AL6: https://app.dimensions.ai/details/grant/grant.14970420 | AM6: 46 Information and Computing Sciences; 4612 Software Engineering | AN6: Bioengineering; Biotechnology; Data Science; Machine Learning and Artificial Intelligence; Networking and Information Technology R&D (NITRD) | AO6: Generic health relevance | AU6: B12 Engineering | AV6: 9 Industry, Innovation and Infrastructure
A7: 2025 Dimensions CM | B7: 410 | C7: grant.15084865 | D7: =ISNUMBER(MATCH(C7, 'Airtable copy'!N:N, 0)) -> FALSE | E7: =VLOOKUP(C7,'Airtable copy'!N:N,1,FALSE) -> #REF! | F7: =ISNUMBER(MATCH(C7, 'Grants tracker download'!O:O, 0)) -> FALSE | G7: =VLOOKUP(C7,'Grants tracker download'!O:O,1,FALSE) -> #REF! | H7: 101182025; 277738; GREENGROCER; 10.3030/101182025 | I7: Maturing food footprint tools, solutions, and uptake to accelerate a rapid EU food transition | J7: Maturing food footprint tools, solutions, and uptake to accelerate a rapid EU food transition | K7: There is a recognized and urgent need for better food footprint data to accurately inform the sustainable food system transition as the current knowledge infrastructure is inadequate both in terms of scientific robustness and real-world suitability for regulatory and business decision support. The objective of GREENGROCER is to make foundation-strengthening investments in critical knowledge infrastructure in order to advance food footprint data from lab to application. The project packages investments across over a dozen leading mainstream tools including Trase, HESTIA, CoolFarm, FABIO, and EXIOBASE, which collectively form the foundation of most food footprint data currently in use. Work in GREENGROCER: 1) improves the scientific depth by revisiting long standing weak areas including on subnational supply chain specificity, reliability information, and novel and neglected products and impacts such as spices, seaweed, insect protein, cellular agriculture, cold chain energy use, and seafloor disturbance; 2) makes foundation-strengthening investments that take all models towards full compliance with the EU’s Product Environmental Footprint standards and improve FAIRness and interoperability; and 3) promotes exploitation through multi-stakeholder dialogue between food system researchers, industry, and regulators aimed at prioritising pain points and supporting effective regulation. Finally, to collate data without yet another centralised repository, the project leverages Europe’s competitive advantage in marrying AI with scientific expertise to pioneer a fact-based AI expert which can interact with and gather the rapidly growing volume of food system science. Aimed at the Horizon Europe work program destination of reducing the environmental impact of the food system, GREENGROCER outputs are oriented around 13 specific relevant EU policy frameworks including FSFS, EUDR, ESRS, CSRD, CSDDD, and the CAP. | L7: There is a recognized and urgent need for better food footprint data to accurately inform the sustainable food system transition as the current knowledge infrastructure is inadequate both in terms of scientific robustness and real-world suitability for regulatory and business decision support. The objective of GREENGROCER is to make foundation-strengthening investments in critical knowledge infrastructure in order to advance food footprint data from lab to application. The project packages investments across over a dozen leading mainstream tools including Trase, HESTIA, CoolFarm, FABIO, and EXIOBASE, which collectively form the foundation of most food footprint data currently in use. Work in GREENGROCER: 1) improves the scientific depth by revisiting long standing weak areas including on subnational supply chain specificity, reliability information, and novel and neglected products and impacts such as spices, seaweed, insect protein, cellular agriculture, cold chain energy use, and seafloor disturbance; 2) makes foundation-strengthening investments that take all models towards full compliance with the EU’s Product Environmental Footprint standards and improve FAIRness and interoperability; and 3) promotes exploitation through multi-stakeholder dialogue between food system researchers, industry, and regulators aimed at prioritising pain points and supporting effective regulation. Finally, to collate data without yet another centralised repository, the project leverages Europe’s competitive advantage in marrying AI with scientific expertise to pioneer a fact-based AI expert which can interact with and gather the rapidly growing volume of food system science. Aimed at the Horizon Europe work program destination of reducing the environmental impact of the food system, GREENGROCER outputs are oriented around 13 specific relevant EU policy frameworks including FSFS, EUDR, ESRS, CSRD, CSDDD, and the CAP. | M7: Yes | N7: Cross-cutting | O7: Impact assessments | Q7: 6999521 | R7: EUR | S7: 7428611 | T7: 2025-09-01 | U7: 2025 | V7: 2029-08-31 | W7: 2029 | Y7: UNIVERSITEIT LEIDEN; HOEGSKOLAN KRISTIANSTAD; TETRA PAK PACKAGING SOLUTIONS AB; NILU KLIMAT OCH MILJOINSTITUTET AB; INESC TEC - INSTITUTO DE ENGENHARIADE SISTEMAS E COMPUTADORES, TECNOLOGIA E CIENCIA; ARBORETICA BV; STIFTELSEN NILU; STIFTELSEN THE STOCKHOLM ENVIRONMENT INSTITUTE; SANTA MARIA AB; ECOLE NORMALE SUPERIEURE; UNIVERSITY OF YORK; BERGISCHE UNIVERSITAET WUPPERTAL; EIDGENOESSISCHE TECHNISCHE HOCHSCHULE ZUERICH; COOL FARM ALLIANCE COMMUNITY INTEREST COMPANY; CLIMATE AND COMPANY PUBLIC AFFAIRS UG; GLOBESCAN INCORPORATED; LATVIJAS UNIVERSITATE; THE CHANCELLOR, MASTERS AND SCHOLARS OF THE UNIVERSITY OF OXFORD; Départ de Sentier; CENTRE NATIONAL DE LA RECHERCHE SCIENTIFIQUE CNRS; ZURCHER HOCHSCHULE FUR ANGEWANDTE WISSENSCHAFTEN; CHALMERS TEKNISKA HOGSKOLA AB | Z7: Leiden University; Kristianstad University; Tetra Pak Packaging Solutions AB; INESC TEC - Institute for Systems and Computer Engineering, Technology and Science; Stockholm Environment Institute; Santa Maria AB; École Normale Supérieure - PSL; University of York; University of Wuppertal; ETH Zurich; Cool Farm Alliance; University of Latvia; University of Oxford; French National Centre for Scientific Research; Zurich University of Applied Sciences; Chalmers University of Technology | AA7: grid.5132.5; grid.16982.34; grid.570819.2; grid.20384.3d; grid.35843.39; grid.534081.b; grid.5607.4; grid.5685.e; grid.7787.f; grid.5801.c; grid.500093.f; grid.9845.0; grid.4991.5; grid.4444.0; grid.19739.35; grid.5371.0 | AB7: Leiden; Kristianstad; Lund; Porto; Stockholm; Paris; York; Wuppertal; Zurich; London; Riga; Oxford; Paris; Winterthur; Gothenburg | AC7: Île-de-France; York; Nordrhein-Westfalen; Oxfordshire | AD7: Netherlands; Sweden; Sweden; Portugal; Sweden; Sweden; France; United Kingdom; Germany; Switzerland; United Kingdom; Latvia; United Kingdom; France; Switzerland; Sweden | AE7: European Commission | AF7: EC & ERC - European Union; cOAlition S | AG7: Belgium | AH7: HORIZON.2.6 - Food, Bioeconomy Natural Resources, Agriculture and Environment (Programme); HORIZON-RIA - HORIZON Research and Innovation Actions (Funding scheme); HORIZON-CL6-2024-ZEROPOLLUTION-01 (Call for proposal) | AI7: Not available | AK7: https://cordis.europa.eu/project/id/101182025 | AL7: https://app.dimensions.ai/details/grant/grant.15084865 | AM7: 30 Agricultural, Veterinary and Food Sciences; 3006 Food Sciences; 46 Information and Computing Sciences | AU7: C18 Law | AV7: 12 Responsible Consumption and Production
A8: 2025 Dimensions CM | B8: 369 | C8: grant.15201033 | D8: =ISNUMBER(MATCH(C8, 'Airtable copy'!N:N, 0)) -> FALSE | E8: =VLOOKUP(C8,'Airtable copy'!N:N,1,FALSE) -> #REF! | F8: =ISNUMBER(MATCH(C8, 'Grants tracker download'!O:O, 0)) -> FALSE | G8: =VLOOKUP(C8,'Grants tracker download'!O:O,1,FALSE) -> #REF! | H8: UKRI633 | I8: Advanced Microchannel Structured SiC Hollow Fibre Membranes for Value-Added Oil Recovery in Precision Fermentation (PF) | J8: Advanced Microchannel Structured SiC Hollow Fibre Membranes for Value-Added Oil Recovery in Precision Fermentation (PF) | K8: Cellular Agriculture Manufacturing involves the production of agricultural products via cell culture. This innovative method significantly diminishes the environmental impact compared to traditional farming by reducing land use, greenhouse gas emissions, and water usage. It also provides enhanced resilience to climate change and enables more distributed manufacturing processes. This approach further generates added value for UK farmers, aligning with the primary goals of the £12 million EPSRC-funded CARMAR Hub. In addition to being assessed on sustainability, societal, and economic metrics, CARMAR's goal of transitioning "from lab to shopping basket" necessitates the development of "novel, underpinning manufacturing technologies". These technologies are designed to achieve necessary process intensities at scale in a cost-effective and sustainable manner. Considering that separation and purification processes account for approximately 15% of the world's energy demand, the innovation of bioseparation processes through the advancement of sophisticated separation technologies will be a key determinant of CARMAR's success. Given the high energy efficiency of membrane separation, which is up to ten times more energy-efficient than conventional separation methods, expertise in polymeric membranes has been secured within the CARMAR consortium. This project aims to further mitigate potential risks associated with chemical compatibility, fouling, and water permeation of polymeric membranes when interacting with a wide range of biomaterials and systems within the CARMAR value chain. To this end, the project is focused on advancing more resilient and high-throughput ceramic membrane technology, thereby elevating the versatility of CARMAR processes by overcoming the limitations of polymeric membranes. To achieve this, we plan to transfer the highly permeable, low fouling, and chemically robust SiC material into an advanced microchannel structured hollow fibre membrane. This membrane, with its high surface area to volume ratio and low permeation resistance, along with its scalable fabrication uniquely available through this project, aims to counteract the high fabrication cost challenge associated with such membranes. Beyond demonstrating its efficacy in bioseparation applications within CARMAR through collaborations, we will extend the benefits of this advanced material to broader research centres/hubs/institutes, such as the biological membrane and bioenergy research and development at Aston University. By providing a new powerful tool for efficient purifications at lower energy consumption, we aim to bring together membrane researchers from biological, polymeric, and ceramic membrane communities, thereby further advancing globally leading membrane innovations for both successful CARMAR and a more resilient UK society. | L8: Cellular Agriculture Manufacturing involves the production of agricultural products via cell culture. This innovative method significantly diminishes the environmental impact compared to traditional farming by reducing land use, greenhouse gas emissions, and water usage. It also provides enhanced resilience to climate change and enables more distributed manufacturing processes. This approach further generates added value for UK farmers, aligning with the primary goals of the £12 million EPSRC-funded CARMAR Hub. In addition to being assessed on sustainability, societal, and economic metrics, CARMAR's goal of transitioning "from lab to shopping basket" necessitates the development of "novel, underpinning manufacturing technologies". These technologies are designed to achieve necessary process intensities at scale in a cost-effective and sustainable manner. Considering that separation and purification processes account for approximately 15% of the world's energy demand, the innovation of bioseparation processes through the advancement of sophisticated separation technologies will be a key determinant of CARMAR's success. Given the high energy efficiency of membrane separation, which is up to ten times more energy-efficient than conventional separation methods, expertise in polymeric membranes has been secured within the CARMAR consortium. This project aims to further mitigate potential risks associated with chemical compatibility, fouling, and water permeation of polymeric membranes when interacting with a wide range of biomaterials and systems within the CARMAR value chain. To this end, the project is focused on advancing more resilient and high-throughput ceramic membrane technology, thereby elevating the versatility of CARMAR processes by overcoming the limitations of polymeric membranes. To achieve this, we plan to transfer the highly permeable, low fouling, and chemically robust SiC material into an advanced microchannel structured hollow fibre membrane. This membrane, with its high surface area to volume ratio and low permeation resistance, along with its scalable fabrication uniquely available through this project, aims to counteract the high fabrication cost challenge associated with such membranes. Beyond demonstrating its efficacy in bioseparation applications within CARMAR through collaborations, we will extend the benefits of this advanced material to broader research centres/hubs/institutes, such as the biological membrane and bioenergy research and development at Aston University. By providing a new powerful tool for efficient purifications at lower energy consumption, we aim to bring together membrane researchers from biological, polymeric, and ceramic membrane communities, thereby further advancing globally leading membrane innovations for both successful CARMAR and a more resilient UK society. | M8: Yes | N8: Fermentation | O8: Bioprocess design | Q8: 258814 | R8: GBP | S8: 327300 | T8: 2025-06-02 | U8: 2025 | V8: 2027-06-02 | W8: 2027 | X8: Zhentao Wu, Ming Xie | Y8: Aston University | Z8: Aston University | AA8: grid.7273.1 | AB8: Birmingham | AD8: United Kingdom | AE8: Engineering and Physical Sciences Research Council | AF8: cOAlition S; UKRI - UK Research and Innovation | AG8: United Kingdom | AH8: Research and Innovation (Project Category) | AI8: Not available | AK8: https://gtr.ukri.org/projects?ref=UKRI633 | AL8: https://app.dimensions.ai/details/grant/grant.15201033 | AM8: 40 Engineering; 4004 Chemical Engineering | AU8: B12 Engineering | AV8: 13 Climate Action; 7 Affordable and Clean Energy
A9: 2025 Dimensions CM | B9: 357 | C9: grant.15054223 | D9: =ISNUMBER(MATCH(C9, 'Airtable copy'!N:N, 0)) -> FALSE | E9: =VLOOKUP(C9,'Airtable copy'!N:N,1,FALSE) -> #REF! | F9: =ISNUMBER(MATCH(C9, 'Grants tracker download'!O:O, 0)) -> FALSE | G9: =VLOOKUP(C9,'Grants tracker download'!O:O,1,FALSE) -> #REF! | H9: 10144450 | I9: Scaling sustainable cocoa butter production using cellular agriculture | J9: Scaling sustainable cocoa butter production using cellular agriculture | K9: For the third year running, cocoa demand has outstripped supply, with a 2023/24 deficit of 462,000 tons predicted by the International Cocoa Organization. Consequently, in April 2024, cocoa prices reached an historic high of USD12,261/ton, compared to around USD3,000/ton in April 2023\. Cocoa yields, which are expected to fall by 11.7% in 2023/24, are already significantly affected by both the climate crisis and prevailing climate patterns (El Nino), which have led to more extreme weather conditions in key cocoa-producing regions. Seasonally wetter conditions have driven devastating fungal disease outbreaks (black pod disease causes 20-30% yield losses globally and up to 100% locally). Seasonally warmer and drier conditions have also driven mealybug outbreaks, exacerbating the spread of endemic viral diseases (cocoa swollen shoot virus disease can cause local yield losses of 15-50%). By 2050, it is estimated that 89.5% of cocoa-producing areas will be less suitable for production. Alongside climate and disease challenges, the rising price of agricultural inputs (including fertiliser and pesticides) has forced farmers to reduce application rates, further reducing yield and profits. With smallholder farmers having limited investment opportunities, cocoa trees are also ageing and less productive. Coupling these production challenges with low farm-gate prices and small farm sizes, the majority of farmers in the two main cocoa-producing countries (Côte d'Ivoire and Ghana) are unable to earn a living income. Consequently, younger generations are increasingly seeking more rewarding employment opportunities. Cocoa continues to be a major driver of deforestation, biodiversity loss, and serious labour issues including child labour and forced labour. With cocoa demand continuing to rise, alternatives to traditional cocoa that can future-proof supplies and offer improved social and environmental impacts are receiving increasing attention. First-generation cocoa alternatives substitute cocoa for natural alternatives (e.g., carob), but they cannot recreate the authentic organoleptic properties of cocoa. Second-generation cocoa alternatives use precision fermentation to recreate key components of cocoa, but because they do not generate the full range of natural compounds in cocoa, they cannot recreate the full organoleptic properties of cocoa. Precision fermentation techniques also rely on energy-intensive genetically modified microbial production processes, which are challenging to scale. Recently, plant cell culture processes have been developed that uniquely offer the opportunity to recreate nature-identical cocoa, without requiring the development or use of genetically modified microbes, and with an energy-efficient and theoretically scalable production process. Here, Extracellular (UK) and Celleste Bio (Israel) will scale plant cell cultured cocoa production. | L9: For the third year running, cocoa demand has outstripped supply, with a 2023/24 deficit of 462,000 tons predicted by the International Cocoa Organization. Consequently, in April 2024, cocoa prices reached an historic high of USD12,261/ton, compared to around USD3,000/ton in April 2023\. Cocoa yields, which are expected to fall by 11.7% in 2023/24, are already significantly affected by both the climate crisis and prevailing climate patterns (El Nino), which have led to more extreme weather conditions in key cocoa-producing regions. Seasonally wetter conditions have driven devastating fungal disease outbreaks (black pod disease causes 20-30% yield losses globally and up to 100% locally). Seasonally warmer and drier conditions have also driven mealybug outbreaks, exacerbating the spread of endemic viral diseases (cocoa swollen shoot virus disease can cause local yield losses of 15-50%). By 2050, it is estimated that 89.5% of cocoa-producing areas will be less suitable for production. Alongside climate and disease challenges, the rising price of agricultural inputs (including fertiliser and pesticides) has forced farmers to reduce application rates, further reducing yield and profits. With smallholder farmers having limited investment opportunities, cocoa trees are also ageing and less productive. Coupling these production challenges with low farm-gate prices and small farm sizes, the majority of farmers in the two main cocoa-producing countries (Côte d'Ivoire and Ghana) are unable to earn a living income. Consequently, younger generations are increasingly seeking more rewarding employment opportunities. Cocoa continues to be a major driver of deforestation, biodiversity loss, and serious labour issues including child labour and forced labour. With cocoa demand continuing to rise, alternatives to traditional cocoa that can future-proof supplies and offer improved social and environmental impacts are receiving increasing attention. First-generation cocoa alternatives substitute cocoa for natural alternatives (e.g., carob), but they cannot recreate the authentic organoleptic properties of cocoa. Second-generation cocoa alternatives use precision fermentation to recreate key components of cocoa, but because they do not generate the full range of natural compounds in cocoa, they cannot recreate the full organoleptic properties of cocoa. Precision fermentation techniques also rely on energy-intensive genetically modified microbial production processes, which are challenging to scale. Recently, plant cell culture processes have been developed that uniquely offer the opportunity to recreate nature-identical cocoa, without requiring the development or use of genetically modified microbes, and with an energy-efficient and theoretically scalable production process. Here, Extracellular (UK) and Celleste Bio (Israel) will scale plant cell cultured cocoa production. | M9: Yes | N9: N/A | O9: N/A | Q9: 249927 | R9: GBP | S9: 316058 | T9: 2025-04-30 | U9: 2025 | V9: 2027-04-29 | W9: 2027 | X9: Jamie Thompson | Y9: EXTRACELLULAR LTD | AE9: Innovate UK | AF9: cOAlition S; UKRI - UK Research and Innovation | AG9: United Kingdom | AH9: Collaborative R&D (Project Category) | AI9: Not available | AK9: https://gtr.ukri.org/projects?ref=10144450 | AL9: https://app.dimensions.ai/details/grant/grant.15054223 | AM9: 30 Agricultural, Veterinary and Food Sciences; 3002 Agriculture, Land and Farm Management | AN9: Complementary and Integrative Health | AU9: A06 Agriculture, Veterinary and Food Science | AV9: 13 Climate Action; 15 Life on Land; 2 Zero Hunger
A10: 2025 Dimensions F | B10: 3162 | C10: grant.14933116 | D10: =ISNUMBER(MATCH(C10, 'Airtable copy'!N:N, 0)) -> FALSE | E10: =VLOOKUP(C10,'Airtable copy'!N:N,1,FALSE) -> #REF! | F10: =ISNUMBER(MATCH(C10, 'Grants tracker download'!O:O, 0)) -> FALSE | G10: =VLOOKUP(C10,'Grants tracker download'!O:O,1,FALSE) -> #REF! | H10: 101214268; 272166; UNICO2RN; 10.3030/101214268 | I10: Flexible and Efficient Capture and Bioconversion of CO2 to Materials and Ingredients | J10: Flexible and Efficient Capture and Bioconversion of CO2 to Materials and Ingredients | K10: The UNICO2RN project aims to demonstrate novel routes to convert biogenic CO2 into ingredients and materials, involving metal organic framework-based capture and purification technology and biotechnological processes based on Hydrogen Oxidizing Bacteria. The modularity and flexibility of the developed processes will be shown through 2 demonstration cases in real industrial settings at TRL 7 for sustainable and efficient production of microbial proteins and PHA, from 2 types of biogenic CO2 sources of different concentration and purity. These new routes bring clear advantages in terms of efficiency, safety, environmental footprint and greenhouse gas emission reductions with respect to benchmarks. Their development to TRL7 will enable their industrialization and thus lead to major positive economic, environmental and social/societal impacts. | L10: The UNICO2RN project aims to demonstrate novel routes to convert biogenic CO2 into ingredients and materials, involving metal organic framework-based capture and purification technology and biotechnological processes based on Hydrogen Oxidizing Bacteria. The modularity and flexibility of the developed processes will be shown through 2 demonstration cases in real industrial settings at TRL 7 for sustainable and efficient production of microbial proteins and PHA, from 2 types of biogenic CO2 sources of different concentration and purity. These new routes bring clear advantages in terms of efficiency, safety, environmental footprint and greenhouse gas emission reductions with respect to benchmarks. Their development to TRL7 will enable their industrialization and thus lead to major positive economic, environmental and social/societal impacts. | M10: Yes | N10: Fermentation | O10: Bioprocess design | Q10: 7499958 | R10: EUR | S10: 7959724 | T10: 2025-06-01 | U10: 2025 | V10: 2029-05-31 | W10: 2029 | Y10: VLAAMSE INSTELLING VOOR TECHNOLOGISCH ONDERZOEK N.V.; NIZO FOOD RESEARCH BV; CO2BIOCLEAN GMBH; VEOLIA NV-SA; LESAFFRE INTERNATIONAL; SABIO SRL; NOVA-INSTITUT FUR POLITISCHE UND OKOLOGISCHE INNOVATION GMBH; IDENER RESEARCH & DEVELOPMENT AIE; MOF TECHNOLOGIES LIMITED; AERBIO A/S; AERBIO BV | Z10: Flemish Institute for Technological Research; Nederlands Instituut Voor Zuivel Oonderzoek; Lesaffre International SARL; Nova Institut | AA10: grid.6717.7; grid.419921.6; grid.700749.d; grid.425930.9 | AB10: Mol; Ede; Hürth | AD10: Belgium; Netherlands; France; Germany | AE10: European Commission | AF10: EC & ERC - European Union; cOAlition S | AG10: Belgium | AH10: HORIZON.2.6 - Food, Bioeconomy Natural Resources, Agriculture and Environment (Programme); HORIZON-JU-IA - HORIZON JU Innovation Actions (Funding scheme); HORIZON-JU-CBE-2024 (Call for proposal) | AI10: Not available | AK10: https://cordis.europa.eu/project/id/101214268 | AL10: https://app.dimensions.ai/details/grant/grant.14933116 | AM10: 40 Engineering; 4004 Chemical Engineering | AU10: B12 Engineering | AV10: 13 Climate Action
A11: 2025 Dimensions F | B11: 2438 | C11: grant.15166434 | D11: =ISNUMBER(MATCH(C11, 'Airtable copy'!N:N, 0)) -> FALSE | E11: =VLOOKUP(C11,'Airtable copy'!N:N,1,FALSE) -> #REF! | F11: =ISNUMBER(MATCH(C11, 'Grants tracker download'!O:O, 0)) -> FALSE | G11: =VLOOKUP(C11,'Grants tracker download'!O:O,1,FALSE) -> #REF! | H11: APVV-24-0069; 47a3727f-b41e-40a8-b1a3-4d27984ab6ba | I11: Sustainable production of microbial proteins and their application in value-added cereal goods manufacturing | J11: Sustainable production of microbial proteins and their application in value-added cereal goods manufacturing | K11: As demand for animal origin food products increases faster than a global production can offer, novel strategies for carbon-neutral food manufacturing are an important part for diversifying food products and ensuring food self-sufficiency. Nowadays, more than one-fifth of global greenhouse gas emissions come from agriculture. Therefore, the development of alternative proteins and their adoption by consumers is critical to reduce negative climate change. Although plant-based alternatives make up 99% of this market, and most other proteins types (insects or microbes) are still in research and development pushing their greater commercialization at the end of this decade. The market with microbial proteins will be driven mainly by the expected increase in the world population, associated with countries' effort to secure food self-sufficiency and current trends in food consumption, which won’t be reachable by conventional agriculture/economy. Among the advantages of microbial proteins is their simple production, which includes a very short production time compared to the duration of growing crops, or raising animals, and also lower land and water requirements. Moreover, already available and producible mycoproteins (used as whole-cell products; without necessity of protein concentration or isolation) contain 40 % protein, have a high fibre content, limited saccharides content and don’t contain cholesterol, which makes them nutritionally more interesting compared to „classic“ proteins. The presented project focuses on potential production of microbial proteins using filamentous fungi and yeast by utilization of waste byproducts from industry. The main waste side-stream would be corn mash (form ethanol production) and glycerol (from biodiesel production). Returning of such waste into production has significant environmental effect. Furthermore, the produced biomass will be employed into process of bakery good production. Thus the effect of usage of these alternative would b | L11: As demand for animal origin food products increases faster than a global production can offer, novel strategies for carbon-neutral food manufacturing are an important part for diversifying food products and ensuring food self-sufficiency. Nowadays, more than one-fifth of global greenhouse gas emissions come from agriculture. Therefore, the development of alternative proteins and their adoption by consumers is critical to reduce negative climate change. Although plant-based alternatives make up 99% of this market, and most other proteins types (insects or microbes) are still in research and development pushing their greater commercialization at the end of this decade. The market with microbial proteins will be driven mainly by the expected increase in the world population, associated with countries' effort to secure food self-sufficiency and current trends in food consumption, which won’t be reachable by conventional agriculture/economy. Among the advantages of microbial proteins is their simple production, which includes a very short production time compared to the duration of growing crops, or raising animals, and also lower land and water requirements. Moreover, already available and producible mycoproteins (used as whole-cell products; without necessity of protein concentration or isolation) contain 40 % protein, have a high fibre content, limited saccharides content and don’t contain cholesterol, which makes them nutritionally more interesting compared to „classic“ proteins. The presented project focuses on potential production of microbial proteins using filamentous fungi and yeast by utilization of waste byproducts from industry. The main waste side-stream would be corn mash (form ethanol production) and glycerol (from biodiesel production). Returning of such waste into production has significant environmental effect. Furthermore, the produced biomass will be employed into process of bakery good production. Thus the effect of usage of these alternative would b | M11: Yes | N11: Fermentation | O11: End product formulation | P11: microbial biomass; circular economy; industrial waste processing; bakery products | Q11: 300000 | R11: EUR | S11: 318365 | T11: 2025-01-09 | U11: 2025 | V11: 2029-08-31 | W11: 2029 | X11: Tatiana Klempová, Milan Čertík, Zlatica Kohajdová, Michaela Lauková, Peter Gajdoš, Lucia Minarovičová | Y11: Research and Development center s.r.o.; Slovak University of Technology in Bratislava, Faculty of Chemical and Food Technology | Z11: Slovak University of Technology in Bratislava | AA11: grid.440789.6 | AB11: Bratislava | AD11: Slovakia | AE11: Slovak Research and Development Agency | AG11: Slovakia | AH11: SR&DA (APVV) Public Call (Program type, financial source) | AI11: Not available | AK11: https://www.skcris.sk/sk/register-projektov/detail/47a3727f-b41e-40a8-b1a3-4d27984ab6ba | AL11: https://app.dimensions.ai/details/grant/grant.15166434 | AM11: 30 Agricultural, Veterinary and Food Sciences; 31 Biological Sciences; 44 Human Society; 4410 Sociology | AU11: A06 Agriculture, Veterinary and Food Science | AV11: 13 Climate Action; 2 Zero Hunger
