Workbook

Sheet Airtable copy
A1: Title | B1: Abstract | C1: Original title | D1: Database | E1: Total amount | F1: Gov contribution | G1: Currency | H1: Total amount (USD) | I1: Gov contribution (USD) | J1: Total amount (EUR) | K1: Gov & NP contribution (EUR) | L1: Funding decision | M1: copy to external database | N1: URL for announcement | O1: Identification code | R1: Notes (external) | S1: Notes (internal) | T1: Project lead (PI) | U1: PI department | V1: PI organisation | W1: PI organisation type | X1: PI organisation country | Y1: PI organisation region | Z1: PI organisation state | AA1: PI organisation zip code | AB1: PI organisation congressional district | AC1: Collaborator names | AD1: Collaborator institutions | AE1: Multiple organisation recipients | AF1: Date request submitted | AG1: Year request submitted | AH1: Date award announced | AI1: Project start date | AJ1: Duration of award (months) | AK1: Project status | AL1: Annual expenditures | AM1: Funder name | AN1: Sub-funder | AO1: Funding call | AP1: Success rate | AQ1: Funder type | AR1: Funder Country | AS1: Funder region | AT1: Production platform | AU1: Sub-production pillar | AV1: microalgae | AW1: Award purpose | AX1: End product type | AY1: sub-end product | AZ1: Research category | BA1: GFI grantee | BB1: APP site | BC1: Minority serving institution | BD1: Date added | BE1: Last modified | BF1: GFI LOS | BG1: Link to LOS | BH1: GFI partner | BI1: Tier | BJ1: Year project started | BK1: End date | BL1: duration (years) | BM1: Years active | BN1: 2020 | BO1: 2021 | BP1: 2022 | BQ1: 2023 | BR1: 2024 | BS1: 2025 | BT1: 2026 | BU1: 2027 | BV1: 2028 | BW1: 2029 | BX1: 2030 | BY1: 2031 | BZ1: 2032 | CA1: 2033 | CB1: 2034 | CC1: 2035
A2: Denmark announces 1 billion kroner for plant-based foods in historic climate agreement | D2: airtable | E2: 1250000000 | F2: 1250000000 | G2: DKK | H2: 177000000 | I2: 177000000 | J2: =E2*0.13 -> 162500000 | K2: =F2*0.13 -> 162500000 | L2: Committed | M2: checked | N2: https://gfieurope.org/blog/denmark-plant-based-investment-in-climate-agreement/ | R2: Original award amount is DKK 1,250,000,000. | S2: In 2021 State of Global Policy Report. 12.04.23: I think this article is an update on this funding: https://www.forbes.com/sites/danieladelorenzo/2023/09/10/denmarks-195-millions-plant-based-fund-receives-overwhelming-number-of-applicants/?sh=3d41434eb034 | T2: TBD | U2: n/a | V2: Multiple | W2: TBD | X2: Denmark | Y2: Europe | Z2: n/a | AE2: Yes | AI2: 44475 | AJ2: 9 | AK2: In progress | AL2: 19666667 | AM2: Danish Government | AQ2: Government | AR2: Denmark | AS2: Europe | AT2: Plant-based | AW2: Research and development, Equipment and infrastructure | AX2: Agnostic | BD2: 45029 | BE2: 45264 | BI2: Tier 4 (No GFI involvement) | BJ2: 2021 | BK2: 47644
A3: Plant2Food | B3: The new collaborative platform Plant2Food will accelerate the development of plant-based foods. Researchers and companies will collaborate in exploring complex challenges within plant and food science and sharing new knowledge across sectors – without taking out patents based on the results. The Novo Nordisk Foundation is supporting the platform with up to DKK 200 million (€27 million) over the next 5 years. It is necessary to convert a big part of our food production to plant-based foods if we want to make the most appropriate use of our agricultural land as well as being able to feed a growing world population. The key to accelerating this transition is developing a greater selection of tasty, nutritious and sustainable plant-based food products that are also affordable to consumers. A new collaboration platform, Plant2Food, will be a hub for researchers and companies who want to collaborate to solve some of the complex issues of developing plant-based foods – without taking out patents based on the results. | D3: airtable | E3: 200000000 | F3: 200000000 | G3: DKK | H3: 28473000 | I3: 0 | J3: =E3*0.13 -> 26000000 | K3: =F3*0.13 -> 26000000 | L3: Awarded | M3: checked | N3: https://novonordiskfonden.dk/en/news/new-open-collaborative-platform-will-accelerate-the-development-of-plant-based-foods/ | R3: Original award amount is DKK 200,000,000. | T3: Marie Louise Conradsen | U3: Natural Sciences | V3: Aarhus University | W3: University | X3: Denmark | Y3: Europe | Z3: n/a | AD3: University of Copenhagen, Technical University of Denmark, Wageningen University and Research, Food and Bio Cluster Denmark | AE3: Yes | AI3: 44875 | AJ3: 5 | AK3: In progress | AL3: 5694600 | AM3: Novo Nordisk Foundation | AQ3: Non-profit | AR3: Denmark | AS3: Europe | AT3: Plant-based | AW3: Research and development | AX3: =IFERROR(INDEX('full database 2024'!AR:AR, MATCH(A3, 'full database 2024'!B:B, 0)), "") | AZ3: cross-cutting | BD3: 44984 | BE3: 45035 | BI3: Tier 4 (No GFI involvement) | BJ3: 2022 | BK3: 2027 | BL3: =BK3-BJ3+1 -> 6 | BM3: =TEXTJOIN(", ", TRUE, SEQUENCE(1, BL3, BJ3)) -> 2022, 2023, 2024, 2025, 2026, 2027 | BN3: =IF(ISNUMBER(SEARCH(BN$1, $BM3)), ($K3/$BL3), "") | BO3: =IF(ISNUMBER(SEARCH(BO$1, $BM3)), ($K3/$BL3), "") | BP3: =IF(ISNUMBER(SEARCH(BP$1, $BM3)), ($K3/$BL3), "") -> 4333333.3 | BQ3: =IF(ISNUMBER(SEARCH(BQ$1, $BM3)), ($K3/$BL3), "") -> 4333333.3 | BR3: =IF(ISNUMBER(SEARCH(BR$1, $BM3)), ($K3/$BL3), "") -> 4333333.3 | BS3: =IF(ISNUMBER(SEARCH(BS$1, $BM3)), ($K3/$BL3), "") -> 4333333.3 | BT3: =IF(ISNUMBER(SEARCH(BT$1, $BM3)), ($K3/$BL3), "") -> 4333333.3 | BU3: =IF(ISNUMBER(SEARCH(BU$1, $BM3)), ($K3/$BL3), "") -> 4333333.3 | ... CC3: =IF(ISNUMBER(SEARCH(CC$1, $BM3)), ($K3/$BL3), "")
A4: CO2 as a sustainable raw material in our future food production | B4: In a new consortium, companies and university researchers will create a sustainable source of proteins for human food derived from CO2. The aim is to help fight the rising global problems with food insecurity and greenhouse-gas emissions from agriculture. Two leading foundations are supporting the initiative with up to DKK 200 million (€27 million). | D4: airtable | E4: 100000000 | F4: 100000000 | G4: DKK | H4: 27000000 | I4: 0 | J4: =E4*0.13 -> 13000000 | K4: =F4*0.13 -> 13000000 | L4: Awarded | M4: checked | N4: https://novonordiskfonden.dk/en/news/co2-as-a-sustainable-raw-material-in-our-future-food-production/ | R4: Original award amount is DKK 200,000,000. Halved to reflect removal of US portion | T4: Claus Crone Fuglsang | U4: n/a | V4: Novozymes A/S | W4: For profit | X4: Denmark | Y4: Europe | Z4: n/a | AD4: Topsoe A/S, Washington University St. Louis, Novo Nordisk Foundation CO2 Research Center (CORC) at Aarhus University | AE4: Yes | AI4: 45078 | AJ4: 2 | AK4: In progress | AL4: 13500000 | AM4: Novo Nordisk Foundation | AQ4: Non-profit | AR4: Denmark | AS4: Europe, North America | AT4: Fermentation | AU4: PF | AW4: Research and development | AX4: =IFERROR(INDEX('full database 2024'!AR:AR, MATCH(A4, 'full database 2024'!B:B, 0)), "") | AZ4: Feedstocks | BD4: 45377 | BE4: 45779 | BI4: Tier 4 (No GFI involvement) | BJ4: 2023 | BK4: 2025 | BL4: =BK4-BJ4+1 -> 3 | BM4: =TEXTJOIN(", ", TRUE, SEQUENCE(1, BL4, BJ4)) -> 2023, 2024, 2025 | BN4: =IF(ISNUMBER(SEARCH(BN$1, $BM4)), ($K4/$BL4), "") | BO4: =IF(ISNUMBER(SEARCH(BO$1, $BM4)), ($K4/$BL4), "") | BP4: =IF(ISNUMBER(SEARCH(BP$1, $BM4)), ($K4/$BL4), "") | BQ4: =IF(ISNUMBER(SEARCH(BQ$1, $BM4)), ($K4/$BL4), "") -> 4333333.3 | BR4: =IF(ISNUMBER(SEARCH(BR$1, $BM4)), ($K4/$BL4), "") -> 4333333.3 | BS4: =IF(ISNUMBER(SEARCH(BS$1, $BM4)), ($K4/$BL4), "") -> 4333333.3 | BT4: =IF(ISNUMBER(SEARCH(BT$1, $BM4)), ($K4/$BL4), "") | BU4: =IF(ISNUMBER(SEARCH(BU$1, $BM4)), ($K4/$BL4), "") | ... CC4: =IF(ISNUMBER(SEARCH(CC$1, $BM4)), ($K4/$BL4), "")
A5: Precision Technology: Biotechnology, smart sensors, and advanced data analysis | B5: The project has three sub-goals: Developing modern biotechnology to produce food Develop spectroscopic methods for food characterization, for the management and optimization of products and processes Develop data analytical methods that convert complex data into relevant, reliable and useful information Three enabling technologies It is necessary to produce more sustainably, reduce food waste and make full use of our raw materials. To achieve this, there is a need for precision technology that enables the food industry to produce the products and qualities needed, while minimizing food waste. This research program will contribute to this by developing three enabling technologies: New biotechnological processes that both provide better utilization of residual raw materials and can be used for the future production of important food components such as protein and fatty acids. We will develop new processes based on combinations of enzymatic protein hydrolysis, precision fermentation and meat cultivation. Smart sensors for rapid measurement of food quality that enable measurement and control of production processes to minimize waste and optimize yield and final quality. We will develop spectroscopic methods for in-line quality control and chemical characterization, and study how these can be applied in systems that facilitate product differentiation, consumer satisfaction and personalized nutrition. Data analytics tools that transform large and complex data into relevant, reliable and usable information. Such tools are essential to unlock the potential of technologies 1 and 2, as well as other scientific disciplines and a modern digitalized food industry. We will specifically work on challenges related to prediction and interpretation of data by combining methods from statistics, chemometrics and machine learning. | D5: airtable | E5: 64200000 | F5: 64200000 | G5: NOK | J5: =E5*0.087 -> 5585400 | K5: =F5*0.087 -> 5585400 | L5: Awarded | M5: checked | N5: https://nofima.no/prosjekt/precision-food-production/ | R5: Original award amount is estimated to be NOK 75,000,000. This was determined from the overall pool of funding available for this call (NOK 300,000,000) and the fact that four programs were awarded funding (300 million / 4 = 75 million). https://www.forskningsradet.no/en/call-for-proposals/2020/nye-strategiske-programmer-for-nofima-2021-2024/. Updated amount - link from funder here: https://prosjektbanken.forskningsradet.no/en/project/FORISS/314111?Kilde=FORISS&distribution=Ar&chart=bar&calcType=funding&Sprak=no&sortBy=score&sortOrder=desc&resultCount=30&offset=30&source=FORISS&projectId=270048&Fritekst=fermentation&Ar=2025&Ar=2024&Ar=2023&Ar=2022&Ar=2021&Ar=2020 | T5: Jens Petter Wold | U5: n/a | V5: Nofima | W5: For profit | X5: Norway | Y5: Europe | Z5: n/a | AC5: Ingrid Måge; Nils Kristian Afseth; Sissel Rønning; Lars Axelsson; Elin Katinka; Riiser Dankel | AD5: Nofima | AE5: No | AI5: 44197 | AJ5: 4 | AK5: In progress | AL5: 1767689 | AM5: Foundation for Research Levy on Agricultural Products (FFL) | AP5: https://www.forskningsradet.no/en/call-for-proposals/2020/nye-strategiske-programmer-for-nofima-2021-2024/ | AQ5: Government | AR5: Norway | AS5: Europe | AT5: Cross-cutting | AU5: CellAg | AW5: Research and development | AX5: =IFERROR(INDEX('full database 2024'!AR:AR, MATCH(A5, 'full database 2024'!B:B, 0)), "") | AZ5: Bioprocess design | BD5: 44985 | BE5: 45036 | BI5: Tier 4 (No GFI involvement) | BJ5: 2021 | BK5: 2025 | BL5: =BK5-BJ5+1 -> 5 | BM5: =TEXTJOIN(", ", TRUE, SEQUENCE(1, BL5, BJ5)) -> 2021, 2022, 2023, 2024, 2025 | BN5: =IF(ISNUMBER(SEARCH(BN$1, $BM5)), ($K5/$BL5), "") | BO5: =IF(ISNUMBER(SEARCH(BO$1, $BM5)), ($K5/$BL5), "") -> 1117080 | BP5: =IF(ISNUMBER(SEARCH(BP$1, $BM5)), ($K5/$BL5), "") -> 1117080 | BQ5: =IF(ISNUMBER(SEARCH(BQ$1, $BM5)), ($K5/$BL5), "") -> 1117080 | BR5: =IF(ISNUMBER(SEARCH(BR$1, $BM5)), ($K5/$BL5), "") -> 1117080 | BS5: =IF(ISNUMBER(SEARCH(BS$1, $BM5)), ($K5/$BL5), "") -> 1117080 | BT5: =IF(ISNUMBER(SEARCH(BT$1, $BM5)), ($K5/$BL5), "") | BU5: =IF(ISNUMBER(SEARCH(BU$1, $BM5)), ($K5/$BL5), "") | ... CC5: =IF(ISNUMBER(SEARCH(CC$1, $BM5)), ($K5/$BL5), "")
A6: SEEDFOOD: Functional and palatable plant seed storage proteins for sustainable foods | B6: The Foundation has awarded one of the 2021 grants to Marianne Nissen Lund, Professor from the Department of Food Science, University of Copenhagen. Marianne Nissen Lund has received a grant of DKK 56 million for the project SEEDFOOD: Functional and Palatable Plant Seed Storage Proteins for Sustainable Foods. The project aims to discover more efficient ways of utilizing protein from rapeseed, which is currently being used for animal feed. Rapeseed is a very widespread crop in northern Europe, but rapeseed protein is mostly used as animal feed rather than as food for humans. The reasons for this include taste and undesirable components and also that rapeseed protein in its natural form is not good at forming the types of structures that are desirable in food. The SEEDFOOD project aims to transform rapeseed protein into a food ingredient and to investigate how it can be processed to be more palatable, including taste and texture. “Rapeseed is promising because it contains many essential amino acids – the ones that people cannot make themselves – and the content is also higher than in other plant sources. Today, however, rapeseed oil is the only rapeseed food product marketed for humans. Using rapeseed in human food requires the removal of the bitterness and creating a palatable texture from this protein source. For example, yogurt should be soft and creamy and not gritty and sticky. In this research, we will create knowledge about how to use rapeseed protein in food and develop techniques to do this. We will not actually develop specific rapeseed-based products, but we aim to create a protein ingredient the food industry can use in plant-based foods for people,” says Marianne Nissen Lund. | D6: airtable | E6: 55900000 | F6: 55900000 | G6: DKK | H6: 8172831 | I6: 0 | J6: =E6*0.13 -> 7267000 | K6: =F6*0.13 -> 7267000 | L6: Awarded | M6: checked | N6: https://novonordiskfonden.dk/en/news/major-grants-awarded-for-research-on-plant-proteins-as-meat-alternatives/ | R6: Original award amount is DKK 55,900,000. | T6: Marianne Nissen Lund | U6: Food Science | V6: University of Copenhagen | W6: University | X6: Denmark | Y6: Europe | Z6: n/a | AE6: No | AI6: 44354 | AJ6: 6 | AK6: In progress | AL6: 1362139 | AM6: Novo Nordisk Foundation | AQ6: Non-profit | AR6: Denmark | AS6: Europe | AT6: Plant-based | AW6: Research and development | AX6: =IFERROR(INDEX('full database 2024'!AR:AR, MATCH(A6, 'full database 2024'!B:B, 0)), "") | AZ6: Ingredient optimisation | BD6: 45020 | BE6: 45035 | BI6: Tier 4 (No GFI involvement) | BJ6: 2021 | BK6: 2027 | BL6: =BK6-BJ6+1 -> 7 | BM6: =TEXTJOIN(", ", TRUE, SEQUENCE(1, BL6, BJ6)) -> 2021, 2022, 2023, 2024, 2025, 2026, 2027 | BN6: =IF(ISNUMBER(SEARCH(BN$1, $BM6)), ($K6/$BL6), "") | BO6: =IF(ISNUMBER(SEARCH(BO$1, $BM6)), ($K6/$BL6), "") -> 1038142.9 | BP6: =IF(ISNUMBER(SEARCH(BP$1, $BM6)), ($K6/$BL6), "") -> 1038142.9 | BQ6: =IF(ISNUMBER(SEARCH(BQ$1, $BM6)), ($K6/$BL6), "") -> 1038142.9 | BR6: =IF(ISNUMBER(SEARCH(BR$1, $BM6)), ($K6/$BL6), "") -> 1038142.9 | BS6: =IF(ISNUMBER(SEARCH(BS$1, $BM6)), ($K6/$BL6), "") -> 1038142.9 | BT6: =IF(ISNUMBER(SEARCH(BT$1, $BM6)), ($K6/$BL6), "") -> 1038142.9 | BU6: =IF(ISNUMBER(SEARCH(BU$1, $BM6)), ($K6/$BL6), "") -> 1038142.9 | ... CC6: =IF(ISNUMBER(SEARCH(CC$1, $BM6)), ($K6/$BL6), "")
A7: National Alternative Proteins Innovation and Knowledge Centre (NAPIC) | B7: To secure a continued supply of safe, tasty, affordable and functional/healthy proteins while supporting Net Zero goals and future-proofing UK food security, a phased-transition towards low-emission alternative proteins (APs) with a reduced reliance on animal agriculture is imperative. However, population-level access to and acceptance of APs is hindered by a highly complex marketplace challenged by taste, cost, health and safety concerns for consumers, and the fear of diminished livelihoods by farmers. Furthermore, complex regulatory pathways and limited access to affordable and accessible scale-up infrastructure impose challenges for industry and SMEs in particular. Synergistic bridging of the UK's trailblazing science and innovation strengths in AP with manufacturing power is key to realising the UK's ambitious growth potential in AP of £6.8B annually and could create 25,000 jobs across multiple sectors. The National Alternative Protein Innovation Centre (NAPIC), a cohesive pan-UK centre, will revolutionise the UK's agri-food sector by harnessing our world-leading science base through a co-created AP strategy across the Discovery?Innovation?Commercialisation pipeline to support the transition to a sustainable, high growth, blended protein bioeconomy using a consumer-driven approach, thereby changing the economics for farmers and other stakeholders throughout the supply chain. Built on four interdisciplinary knowledge pillars, PRODUCE, PROCESS, PERFORM and PEOPLE covering the entire value chain of AP, we will enable an efficacious and safe translation of new transformative technologies unlocking the benefits of APs. Partnering with global industry, regulators, investors, academic partners and policymakers, and engaging in an open dialogue with UK citizens, NAPIC will produce a clear roadmap for the development of a National Protein Strategy for the UK. NAPIC will enable us to PRODUCE tasty, nutritious, safe, and affordable AP foods and feedstocks necessary to safeguard present and future generations, while reducing concerns about ultra-processed foods and assisting a just-transition for producers. Our PROCESS Pillar will catalyse bioprocessing at scale, mainstreaming cultivated meat and precision fermentation, and diversify AP sources across the terrestrial and aquatic kingdoms of life, delivering economies of scale. Delivering a just-transition to an AP-rich future, we will ensure AP PERFORM, both pre-consumption, and post-consumption, safeguarding public health. Finally, NAPIC is all about PEOPLE, guiding a consumers' dietary transition, and identifying new business opportunities for farmers, future-proofing the UK's protein supply against reliance on imports. Working with UK industry, the third sector and academia, NAPIC will create a National Knowledge base for AP addressing the unmet scientific, commercial, technical and regulatory needs of the sector, develop new tools and standards for product quality and safety and simplify knowledge transfer by catalysing collaboration. NAPIC will ease access to existing innovation facilities and hubs, accelerating industrial adoption underpinned by informed regulatory pathways. We will develop the future leaders of this rapidly evolving sector with bespoke technical, entrepreneurial, regulatory and policy training, and promote knowledge exchange through our unrivalled international network of partners across multiple continents including Protein Industries Canada and the UK-Irish Co-Centre, SUREFOOD. NAPIC will provide a robust and sustainable platform of open innovation and responsible data exchange that mitigates risks associated with this emerging sector and addresses concerns of consumers and producers. Our vision is to make "alternative proteins mainstream for a sustainable planet" and our ambition is to deliver a world-leading innovation and knowledge centre to put the UK at the forefront of the fights for population health equity and against climate change. | D7: airtable | E7: 38000000 | F7: 16001352 | G7: GBP | H7: 48859450 | I7: 18697500 | J7: =E7*1.19 -> 45220000 | K7: =F7*1.19 -> 19041609 | L7: Awarded | M7: checked | N7: https://www.ukri.org/news/national-alternative-protein-innovation-centre-launches/ | O7: grant.14485806 | R7: Original fund amount is GBP 15,000,000. | S7: Per GFI Europe August Report: BBSRC and Innovate UK announced a £15 million investment over 5 years to support the development of an Alternative Proteins Innovation and Knowledge Centre (IKC). The Alternative Proteins IKC will support collaborative research partnerships between businesses and academic researchers and create a nucleating point for the growth of the alternative protein industry in the UK. This announcement follows on from the work that GFI Europe (particularly Seren, Stella and Linus) has done over the past two years engaging with BBSRC and Innovate UK on funding priorities in this space, which led to alternative proteins going into their strategic plans as a priority area for co-investment, and which had already led to the £16m call on Novel Foods they launched earlier in the year. | T7: Anwesha Sarkar | U7: n/a | V7: University Of Leeds | W7: University | X7: UK | Y7: Europe | Z7: n/a | AI7: 45515 | AJ7: 5 | AK7: In progress | AL7: 9771890 | AM7: UK Research and Innovation (UKRI) | AN7: Biotechnology and Biological Sciences Research Council (BBSRC) | AP7: https://www.ukri.org/opportunity/alternative-proteins-innovation-and-knowledge-centre/ | AQ7: Government | AR7: United Kingdom | AS7: Europe | AT7: Cross-cutting | AW7: Research and development, Education and training, Research infrastructure, Networking | AX7: Agnostic | AZ7: cross-cutting | BD7: 45177 | BE7: 45779 | BH7: checked | BI7: Tier 2 (Significant GFI involvement) | BJ7: 2024 | BK7: 2029 | BL7: =BK7-BJ7+1 -> 6 | BM7: =TEXTJOIN(", ", TRUE, SEQUENCE(1, BL7, BJ7)) -> 2024, 2025, 2026, 2027, 2028, 2029 | BN7: =IF(ISNUMBER(SEARCH(BN$1, $BM7)), ($K7/$BL7), "") | BO7: =IF(ISNUMBER(SEARCH(BO$1, $BM7)), ($K7/$BL7), "") | BP7: =IF(ISNUMBER(SEARCH(BP$1, $BM7)), ($K7/$BL7), "") | BQ7: =IF(ISNUMBER(SEARCH(BQ$1, $BM7)), ($K7/$BL7), "") | BR7: =IF(ISNUMBER(SEARCH(BR$1, $BM7)), ($K7/$BL7), "") -> 3173601.5 | BS7: =IF(ISNUMBER(SEARCH(BS$1, $BM7)), ($K7/$BL7), "") -> 3173601.5 | BT7: =IF(ISNUMBER(SEARCH(BT$1, $BM7)), ($K7/$BL7), "") -> 3173601.5 | BU7: =IF(ISNUMBER(SEARCH(BU$1, $BM7)), ($K7/$BL7), "") -> 3173601.5 | ... CC7: =IF(ISNUMBER(SEARCH(CC$1, $BM7)), ($K7/$BL7), "")
A8: Germany Earmarks €38M Investment for Alt-Protein Transition in 2024 Federal Budget | D8: airtable | E8: 38000000 | F8: 38000000 | G8: EUR | H8: 41115050 | I8: 41115050 | J8: 38000000 | K8: 38000000 | L8: Committed | M8: checked | N8: https://www.greenqueen.com.hk/germany-federal-budget-bundestag-2024-38-million-investment-alt-protein-plant-based/?utm_source=foodtechweekly.beehiiv.com&utm_medium=newsletter&utm_campaign=foodtech-weekly-174-by-daniel-s-ruben | R8: Original amount committed is EUR 38,000,000. | S8: From Ivo's email on Nov. 17, 2023: "We have been closely supporting this path and, together with these MPs, we have been working on the topic in an "Alternative Proteins Roundtable" since September 2022 and have actively helped to shape and initiate the measures adopted this week. In particular, the topic of a competence centre and an alternative protein strategy was introduced to this group primarily by us as GFI, but of course we were also calling for all the other measures agreed." | T8: TBD | U8: n/a | V8: TBD | W8: TBD | X8: Germany | Y8: Europe | Z8: n/a | AE8: Yes | AI8: 45292 | AJ8: 1 | AK8: Not started | AL8: 41115050 | AM8: Federal Ministry of Food and Agriculture (BMEL) | AQ8: Government | AR8: Germany | AS8: Europe | AT8: Cross-cutting | AU8: Agnostic | AW8: Research and development, Education and training, Equipment and infrastructure | AX8: Agnostic | BD8: 45264 | BE8: 45264 | BI8: Tier 2 (Significant GFI involvement) | BJ8: 2024 | BK8: 45658
A9: Solar Foods receives a €34 million grant to ramp-up Factory 01 and start preparations for Factory 02 | D9: airtable | E9: 34000000 | F9: 34000000 | G9: EUR | H9: 37298680 | I9: 37298680 | J9: 34000000 | K9: 34000000 | L9: Awarded | M9: checked | N9: https://solarfoods.com/solar-foods-receives-a-34-million-grant-to-ramp-up-factory-01-and-start-preparations-for-factory-02/ | R9: Original award amount is EUR 34,000,000. | T9: Pasi Vainikka | U9: n/a | V9: Solar Foods | W9: For profit | X9: Finland | Y9: Europe | Z9: n/a | AE9: No | AI9: 44917 | AJ9: 3 | AK9: In progress | AL9: 12432893 | AM9: Business Finland | AQ9: Government | AR9: Finland | AS9: Europe | AT9: Fermentation | AU9: PF | AW9: Equipment and infrastructure | AX9: =IFERROR(INDEX('full database 2024'!AR:AR, MATCH(A9, 'full database 2024'!B:B, 0)), "") | AZ9: Bioprocess design, Feedstocks, End product formulation, Food safety & quality | BD9: 45034 | BE9: 45035 | BI9: Tier 4 (No GFI involvement) | BJ9: 2022 | BK9: 2025 | BL9: =BK9-BJ9+1 -> 4 | BM9: =TEXTJOIN(", ", TRUE, SEQUENCE(1, BL9, BJ9)) -> 2022, 2023, 2024, 2025 | BN9: =IF(ISNUMBER(SEARCH(BN$1, $BM9)), ($K9/$BL9), "") | BO9: =IF(ISNUMBER(SEARCH(BO$1, $BM9)), ($K9/$BL9), "") | BP9: =IF(ISNUMBER(SEARCH(BP$1, $BM9)), ($K9/$BL9), "") -> 8500000 | BQ9: =IF(ISNUMBER(SEARCH(BQ$1, $BM9)), ($K9/$BL9), "") -> 8500000 | BR9: =IF(ISNUMBER(SEARCH(BR$1, $BM9)), ($K9/$BL9), "") -> 8500000 | BS9: =IF(ISNUMBER(SEARCH(BS$1, $BM9)), ($K9/$BL9), "") -> 8500000 | BT9: =IF(ISNUMBER(SEARCH(BT$1, $BM9)), ($K9/$BL9), "") | BU9: =IF(ISNUMBER(SEARCH(BU$1, $BM9)), ($K9/$BL9), "") | ... CC9: =IF(ISNUMBER(SEARCH(CC$1, $BM9)), ($K9/$BL9), "")
A10: Green technology for plant-based food (GreenPlantFood) | B10: To maintain national food self-sufficiency and employment, and competitiveness of the Norwegian agricultural sector and food industry there is need for more knowledge on the selection of suitable plant material combined with green technology processing. The main objective in this project is to facilitate green technology towards plant-based food in Norway with a significant proportion of Nordic Raw Materials into attractive and healthy products with low environmental footprint. Furthermore, a project looking at extended utilisation of protein sources, needs to focus on their complete utilization, including side streams. Pulses (peas and faba beans), together with cereals (oat and barley), are realistic candidates for extended food uses as is, or as protein sources. It is also a goal to find replacement for soya, which is imported and have a negative environmental footprint. Pulses are high-quality protein sources but contain a range of different compounds (polysaccharides, fat, polyphenols, anti-nutrients etc) that needs attention through green processing solutions. Farmers and advisors will benefit from understanding which varieties to grow, the best suited regions and quality parameters sought by the Norwegian food industry for plant-based products. | D10: airtable | E10: 27600000 | F10: 27600000 | G10: NOK | H10: 2604048 | I10: 2604048 | J10: =E10*0.087 -> 2401200 | K10: =F10*0.087 -> 2401200 | L10: Awarded | M10: checked | N10: https://nofima.com/projects/green-technology-for-plant-based-food/ | O10: grant.9641296 | R10: Original award amount is NOK 27,600,000 according to the Research Council of Norway website: https://prosjektbanken.forskningsradet.no/en/project/FORISS/319049?Kilde=FORISS&distribution=Ar&chart=bar&calcType=funding&Sprak=no&sortBy=score&sortOrder=desc&resultCount=30&offset=0&Fritekst=GreenPlantFood | T10: Svein Halvor Knutsen | U10: n/a | V10: Nofima | W10: For profit | X10: Norway | Y10: Europe | Z10: n/a | AC10: Sveinung Grimsby; Stefan Sahlstrøm | AD10: Nofima, Lantmännen Cerealia, AM Nutrition, Norgesmøllene, Hoff SA, Mills AS, Flowfood AS, Norwegian University of Life Sciences (NMBU), Norwegian Institute of Bioeconomy Research (NIBIO), NORSUS Norwegian Institute for Sustainability Research, Technical University of Denmark, Potsdam Institute for Climate Impact Research, "Instituto de Biologia Experimental e Tecnológica, Lisboa (iBET)", University of food technologies Plovdiv | AE10: Yes | AI10: 44287 | AJ10: 4 | AK10: In progress | AL10: 651012 | AM10: Research Council of Norway | AQ10: Government | AR10: Norway | AS10: Europe | AT10: Plant-based | AW10: Research and development | AX10: =IFERROR(INDEX('full database 2024'!AR:AR, MATCH(A10, 'full database 2024'!B:B, 0)), "") | AZ10: Ingredient optimisation | BD10: 45037 | BE10: 45037 | BI10: Tier 4 (No GFI involvement) | BJ10: 2021 | BK10: 2025 | BL10: =BK10-BJ10+1 -> 5 | BM10: =TEXTJOIN(", ", TRUE, SEQUENCE(1, BL10, BJ10)) -> 2021, 2022, 2023, 2024, 2025 | BN10: =IF(ISNUMBER(SEARCH(BN$1, $BM10)), ($K10/$BL10), "") | BO10: =IF(ISNUMBER(SEARCH(BO$1, $BM10)), ($K10/$BL10), "") -> 480240 | BP10: =IF(ISNUMBER(SEARCH(BP$1, $BM10)), ($K10/$BL10), "") -> 480240 | BQ10: =IF(ISNUMBER(SEARCH(BQ$1, $BM10)), ($K10/$BL10), "") -> 480240 | BR10: =IF(ISNUMBER(SEARCH(BR$1, $BM10)), ($K10/$BL10), "") -> 480240 | BS10: =IF(ISNUMBER(SEARCH(BS$1, $BM10)), ($K10/$BL10), "") -> 480240 | BT10: =IF(ISNUMBER(SEARCH(BT$1, $BM10)), ($K10/$BL10), "") | BU10: =IF(ISNUMBER(SEARCH(BU$1, $BM10)), ($K10/$BL10), "") | ... CC10: =IF(ISNUMBER(SEARCH(CC$1, $BM10)), ($K10/$BL10), "")
A11: SYLPLANT | B11: Arbiom, an agricultural-biotech company developing solutions to deliver next generation protein ingredients, announced today the kick-off of SYLPLANT project. This European collaborative project gathers 17 partners covering the entire food and feed value chains from feedstock manufacturers to retailers. It is co-funded by the Circular Bio-based Europe Joint Undertaking (CBE JU), a public-private partnership between the European Commission and the Bio-based Industries Consortium. SYLPLANT is built on the success of Sylfeed, a 4-year project funded by the Bio-Based Industries Joint Undertaking (predecessor of CBE JU) where Arbiom successfully scaled-up its technology and validated the performance of SylPro®, its flagship ingredient. “This factory paves the way to Arbiom’s industrial deployment. It will bring 10.000 tons/year of alternative, highly nutritional and sustainable protein to the market to answer the future food needs.” said Marc CHEVREL, CEO of Arbiom. | D11: airtable | E11: 23000000 | F11: 14000000 | G11: EUR | H11: 25829000 | I11: 15722000 | J11: 23000000 | K11: 14000000 | L11: Awarded | M11: checked | N11: https://acrobat.adobe.com/link/review?uri=urn%3Aaaid%3Ascds%3AUS%3Ad4e64a40-4679-3c42-a80f-ca1d80a890fd | R11: Original award amount is EUR 23,000,000 with EUR 14,000,000 from EU government. | T11: Amélie Drouault | U11: n/a | V11: Arbiom | W11: For profit | X11: France | Y11: Europe | Z11: n/a | AD11: FIBENOL, CENTRE DE RECHERCHE ET D’INNOVATION DE L’INSTITUT LYFE (EX INSTITUT PAUL BOCUSE) , SATT SAYENS, Bel, AGROMOUSQUETAIRES, Biozoon GmbH, CENTIV GMBH, NORMANDISE PET FOOD, BIOMAR AS, EUROFINS FOOD TESTING FRANCE, IFEU - INSTITUTE FOR ENERGY AND ENVIRONMENTAL RESEARCH HEIDELBERG, BIOECONOMY FOR CHANGE, PNO CONSULTANTS | AE11: Yes | AI11: 45078 | AJ11: 3 | AK11: In progress | AL11: 8609667 | AM11: European Commission | AN11: Circular Bio-based Europe Joint Undertaking (CBE JU) | AQ11: Joint public/private partnership | AR11: EU | AS11: Europe | AT11: Fermentation | AU11: BF | AW11: Equipment and infrastructure, Research and development | AX11: =IFERROR(INDEX('full database 2024'!AR:AR, MATCH(A11, 'full database 2024'!B:B, 0)), "") | AZ11: End product formulation | BD11: 45120 | BE11: 45123 | BI11: Tier 4 (No GFI involvement) | BJ11: 2023 | BK11: 2026 | BL11: =BK11-BJ11+1 -> 4 | BM11: =TEXTJOIN(", ", TRUE, SEQUENCE(1, BL11, BJ11)) -> 2023, 2024, 2025, 2026 | BN11: =IF(ISNUMBER(SEARCH(BN$1, $BM11)), ($K11/$BL11), "") | BO11: =IF(ISNUMBER(SEARCH(BO$1, $BM11)), ($K11/$BL11), "") | BP11: =IF(ISNUMBER(SEARCH(BP$1, $BM11)), ($K11/$BL11), "") | BQ11: =IF(ISNUMBER(SEARCH(BQ$1, $BM11)), ($K11/$BL11), "") -> 3500000 | BR11: =IF(ISNUMBER(SEARCH(BR$1, $BM11)), ($K11/$BL11), "") -> 3500000 | BS11: =IF(ISNUMBER(SEARCH(BS$1, $BM11)), ($K11/$BL11), "") -> 3500000 | BT11: =IF(ISNUMBER(SEARCH(BT$1, $BM11)), ($K11/$BL11), "") -> 3500000 | BU11: =IF(ISNUMBER(SEARCH(BU$1, $BM11)), ($K11/$BL11), "") | ... CC11: =IF(ISNUMBER(SEARCH(CC$1, $BM11)), ($K11/$BL11), "")
A12: University of Bath Cellular Agriculture Manufacturing Hub (CARMA) | B12: Imagine being able to manufacture food anywhere in the world, or even in space, so everyone, everywhere, has enough nutritious food to eat! This dream can be achieved through Cellular Agriculture (Cell Ag). Cell Ag enables the production of food products that would normally come from an animal, such as meat and milk from cows, or from monocultures of crops such as oil palm trees, without having to keep increasing animal or plant numbers to feed our growing global population. Cell Ag, uses biological cell-level processes to create food via the 'building blocks of life' - the proteins, fats and carbohydrates. By delivering these building blocks, Cell Ag will transform food production by complementing traditional food production, so not only can we feed the world, but we can manufacture the food so that sustainability and social responsibility is embedded from the outset. Why would we wish to use Cell Ag rather than animals? Let's take the example of the building block, protein, from traditional meat. Life Cycle Assessments have shown that when comparing traditional meat manufacturing against the expected benefits of using Cell Ag, there is a predicted reduction in greenhouse gas emissions, and land use, of up to 95%. The analysis also estimates that we could achieve up to 50% reduction in the use of water, compared to cattle farming. And we could reduce need for intensive farming so improving animal welfare too. So, with these benefits and the urgent need to achieve Net Zero Manufacturing and protect the planets resources. Why do we not have Cell Ag manufacturing in our homes or across all our food manufacturing sectors? There are several reasons - and our research will remove these blockers to Cell Ag manufacturing. Current status of Cell Ag Manufacturing research and outputs in the UK: In the UK (and across the World), there are pockets of excellent research being done, but little that focuses on delivering useable and scalable manufacturing machinery, processes, and systems in a coherent manner. The research tends to be in silos and focussed on aspects of the Manufacturing Value Chain. There are fundamental areas of research that need to be delivered to enable us to realise the Cell Ag potential, as well as transforming current research outputs to be useable. Through this Hub we will bring together the pockets of excellence in the UK, and deliver a coherent and targeted research programme that will ensure the UK Cell Ag research ecosystem is world-leading and has manufacturing impact. Rather than target a particular sector/type of food/product - the Hub will deliver manufacturing research which will enable production of food building blocks at local, regional and international levels. Our vision is to be the world leader in delivering materials, manufacturing processes and skills to escalate the world's adoption of sustainable Cell Ag food production. We will achieve this through becoming the net exporter of the building blocks of life. | D12: airtable | E12: 21214469 | F12: 12302109 | G12: GBP | H12: 26130285 | I12: 15655848 | J12: =E12*1.19 -> 25245218 | K12: =F12*1.19 -> 14639510 | L12: Awarded | M12: checked | N12: https://gtr.ukri.org/projects?ref=EP%2FX038114%2F1 | O12: grant.13519746 | R12: Original award amount is GBP 21,214,469 with GBP 12,302,109 coming from government. | S12: GFI Europe helped with the proposal and will sit on the advisory board. | T12: Marianne Ellis | U12: Chemical Engineering | V12: University of Bath | W12: University | X12: UK | Y12: Europe | Z12: n/a | AD12: Royal Agricultural University, University College London (UCL), University of Aberystwyth, University of Birmingham, 3D Bio-Tissues Ltd, Campden BRI, Cellular Agriculture Ltd, Clean Food Group, Hoxton Farms, MilliporeSigma, Multus Biotechnology Limited, Naturbeads Ltd, Qkine Ltd, Quest Meat, Roslin Technologies Limited, Veolia Water Technologies, Ivy Farm Technologies Limited | AE12: Yes | AI12: 45108 | AJ12: 7 | AK12: Not started | AL12: 3732898 | AM12: UK Research and Innovation (UKRI) | AN12: Engineering and Physical Sciences Research Council (EPSRC) | AO12: research hub | AQ12: Joint public/private partnership | AR12: United Kingdom | AS12: Europe | AT12: Cross-cutting | AU12: CellAg | AW12: Research and development, Education and training | AX12: =IFERROR(INDEX('full database 2024'!AR:AR, MATCH(A12, 'full database 2024'!B:B, 0)), "") | AZ12: cross-cutting | BA12: checked | BD12: 45014 | BE12: 45779 | BF12: checked | BH12: checked | BI12: Tier 2 (Significant GFI involvement) | BJ12: 2023 | BK12: 2030 | BL12: =BK12-BJ12+1 -> 8 | BM12: =TEXTJOIN(", ", TRUE, SEQUENCE(1, BL12, BJ12)) -> 2023, 2024, 2025, 2026, 2027, 2028, 2029, 2030 | BN12: =IF(ISNUMBER(SEARCH(BN$1, $BM12)), ($K12/$BL12), "") | BO12: =IF(ISNUMBER(SEARCH(BO$1, $BM12)), ($K12/$BL12), "") | BP12: =IF(ISNUMBER(SEARCH(BP$1, $BM12)), ($K12/$BL12), "") | BQ12: =IF(ISNUMBER(SEARCH(BQ$1, $BM12)), ($K12/$BL12), "") -> 1829938.7 | BR12: =IF(ISNUMBER(SEARCH(BR$1, $BM12)), ($K12/$BL12), "") -> 1829938.7 | BS12: =IF(ISNUMBER(SEARCH(BS$1, $BM12)), ($K12/$BL12), "") -> 1829938.7 | BT12: =IF(ISNUMBER(SEARCH(BT$1, $BM12)), ($K12/$BL12), "") -> 1829938.7 | BU12: =IF(ISNUMBER(SEARCH(BU$1, $BM12)), ($K12/$BL12), "") -> 1829938.7 | ... CC12: =IF(ISNUMBER(SEARCH(CC$1, $BM12)), ($K12/$BL12), "")
A13: ARRIVAL (ARRIVAL of Cellular Agriculture-Enabling biotechnology for Future Food Production) | B13: Global food production must increase more than 60% towards 2050, and as a result, there has been increasing pressure on the livestock sector to meet the growing demand for high-value animal protein. Although plant-based alternatives have a lot of potentials, these cannot truly mimic animal proteins, recreate the nutritional value, nor the mouthfeel, taste, or functionality. Also, from a circular bioeconomy perspective, increased recycling of waste streams from food production will be necessary. We will employ ground-breaking new, enabling, and fundamentally different technologies to produce food proteins by Cellular Agriculture (CellAg). There are two kinds of CellAg production systems, precision fermentation, and cultured meat, and in ARRIVAL we will use both to produce milk, egg, and meat proteins, homologous to proteins normally produced through conventional agriculture, using Norwegian raw materials and by-products as input. CellAg is a revolution in food production that can lead to major changes in agricultural production and ownership, land use, policymaking, food habits, and ethical questions. In ARRIVAL we aim to enable wider implementation of alternative animal protein sources in food production chains, as well as preparing society, consumers, and the food industry for the potential impacts of this radical shift in production methods. In addition to investigating the technological changes CellAg represents, we will through a transdisciplinary approach explore the foundations that must be laid before Norwegian consumers and society will and can adapt to this technology. Through ARRIVAL we will develop enabling biotechnology and knowledge, which will improve and modernize the existing land-based food industry. The novel biotechnological methodology to be developed will in long term potentially be the foundation of a new kind of Norwegian food industry that will produce tomorrow's food in a smart, sustainable, and innovative way. | D13: airtable | E13: 20000000 | F13: 20000000 | G13: NOK | H13: 1993440 | I13: 1993440 | J13: =E13*0.087 -> 1740000 | K13: =F13*0.087 -> 1740000 | L13: Awarded | M13: checked | N13: https://nofima.com/press-release/norwegian-focus-on-new-food-technology/ | O13: grant.13201908 | R13: Original award amount is NOK 20,000,000. | T13: Sissel Beate Rønning | U13: n/a | V13: Nofima | W13: For profit | X13: Norway | Y13: Europe | Z13: n/a | AD13: Sintef Industry, OsloMet, Ruralis, The Norwegian Board of Technology, Nortura AS, Norilia AS, TINE AS | AE13: Yes | AI13: 44927 | AJ13: 4 | AK13: In progress | AL13: 498360 | AM13: Research Council of Norway | AQ13: Government | AR13: Norway | AS13: Europe | AT13: Cross-cutting | AU13: CellAg | AW13: Research and development | AX13: =IFERROR(INDEX('full database 2024'!AR:AR, MATCH(A13, 'full database 2024'!B:B, 0)), "") | AZ13: Cell culture media, Host strain development , Bioprocess design | BD13: 44959 | BE13: 45779 | BI13: Tier 4 (No GFI involvement) | BJ13: 2023 | BK13: 2027 | BL13: =BK13-BJ13+1 -> 5 | BM13: =TEXTJOIN(", ", TRUE, SEQUENCE(1, BL13, BJ13)) -> 2023, 2024, 2025, 2026, 2027 | BN13: =IF(ISNUMBER(SEARCH(BN$1, $BM13)), ($K13/$BL13), "") | BO13: =IF(ISNUMBER(SEARCH(BO$1, $BM13)), ($K13/$BL13), "") | BP13: =IF(ISNUMBER(SEARCH(BP$1, $BM13)), ($K13/$BL13), "") | BQ13: =IF(ISNUMBER(SEARCH(BQ$1, $BM13)), ($K13/$BL13), "") -> 348000 | BR13: =IF(ISNUMBER(SEARCH(BR$1, $BM13)), ($K13/$BL13), "") -> 348000 | BS13: =IF(ISNUMBER(SEARCH(BS$1, $BM13)), ($K13/$BL13), "") -> 348000 | BT13: =IF(ISNUMBER(SEARCH(BT$1, $BM13)), ($K13/$BL13), "") -> 348000 | BU13: =IF(ISNUMBER(SEARCH(BU$1, $BM13)), ($K13/$BL13), "") -> 348000 | ... CC13: =IF(ISNUMBER(SEARCH(CC$1, $BM13)), ($K13/$BL13), "")
A14: Sustainable use of marine and industrial waters to unlock the potential of seaweeds as a future food source | B14: Seaweed farming offers a unique possibility to feed the growing global population without putting further pressure on access to land and fresh water.Also, there is no need for fertilizers but rather a net uptake of nutrients, thereby mitigating eutrophication. Seaweed farming offers a unique possibility to feed the growing global population without putting further pressure on access to land and fresh water. Also, there is no need for fertilizers but rather a net uptake of nutrients, thereby mitigating eutrophication. SUSWEED aims at releasing the potential of Swedish seaweed as a future sustainable food source according to models which have positive effects on both marine and industrial waters. This will be achieved via development of novel cultivation techniques for Ulva fenestrata and Palmaria palmata based both in the ocean and as part of a system to purify nutrient-rich food industry process waters. Harvested seaweed will be stabilized and pre-processed into tasty, nutritious, and safe intermediate raw materials to incorporate in new fish-based and vegan food products. These are developed to reach broad acceptance for seaweed as a new sustainable food commodity. SUSWEED puts great emphasis on solving non-technical challenges of the new industrial symbiosis between seaweed farmers and generators of process waters and other resources which can make the seaweed industry more sustainable. Safety is carefully addressed by monitoring levels of heavy metals and their accessibility for uptake. The project is built on a strong multidisciplinary partnership with industries and academia which has pioneered the development of state-of-the-art research and applications concerning seaweed in Sweden during the last 10 years. | D14: airtable | E14: 19991495 | F14: 19991495 | G14: SEK | H14: 1879201 | I14: 1879201 | J14: =E14*0.091 -> 1819226 | K14: =F14*0.091 -> 1819226 | L14: Awarded | M14: checked | N14: https://research.chalmers.se/en/project/11357 | V14: University of Gothenburg | X14: Sweden | Y14: Europe | AI14: 44938 | AJ14: 61 | AK14: Ended | AL14: 30807 | AM14: Swedish Research Council for Environment Agricultural Sciences and Spatial Planning (FORMAS) | AQ14: Government | AR14: Sweden | AS14: Europe | AT14: Plant-based | AW14: Research and development | AX14: =IFERROR(INDEX('full database 2024'!AR:AR, MATCH(A14, 'full database 2024'!B:B, 0)), "") | AZ14: End product formulation, Crop development, Ingredient optimisation | BD14: 45596 | BE14: 45596 | BJ14: 2023 | BK14: 2031 | BL14: =BK14-BJ14+1 -> 9 | BM14: =TEXTJOIN(", ", TRUE, SEQUENCE(1, BL14, BJ14)) -> 2023, 2024, 2025, 2026, 2027, 2028, 2029, 2030, 2031 | BN14: =IF(ISNUMBER(SEARCH(BN$1, $BM14)), ($K14/$BL14), "") | BO14: =IF(ISNUMBER(SEARCH(BO$1, $BM14)), ($K14/$BL14), "") | BP14: =IF(ISNUMBER(SEARCH(BP$1, $BM14)), ($K14/$BL14), "") | BQ14: =IF(ISNUMBER(SEARCH(BQ$1, $BM14)), ($K14/$BL14), "") -> 202136.23 | BR14: =IF(ISNUMBER(SEARCH(BR$1, $BM14)), ($K14/$BL14), "") -> 202136.23 | BS14: =IF(ISNUMBER(SEARCH(BS$1, $BM14)), ($K14/$BL14), "") -> 202136.23 | BT14: =IF(ISNUMBER(SEARCH(BT$1, $BM14)), ($K14/$BL14), "") -> 202136.23 | BU14: =IF(ISNUMBER(SEARCH(BU$1, $BM14)), ($K14/$BL14), "") -> 202136.23 | ... CC14: =IF(ISNUMBER(SEARCH(CC$1, $BM14)), ($K14/$BL14), "")
A15: GRAPHENE MEMBRANES - FUTURE ENABLER FOR BETTER PLANT-BASED FOODS AND BEVERAGES | B15: The aim of this project is to explore the application of graphene oxide (GO) membranes for more healthy, sustainable, and responsible plant-based food and beverages production. Graphene has unique applications in chemistry and biology due to possibility of attaching various chemical functional group. This allows construction of active membranes to form a perfect separation of organic molecule. A plant-based lifestyle can lower the impact of climate change, but exclusive plant-based diets could also have negative effect on humans. This project resolves these challenges by applying a novel membrane technology to plant-based foods and beverages separation. Obtained knowledge and scientific results could have multiple applications and far reaching impact. The project will target selective removal of sugars, alcohol, and acids to obtain a more balanced plant-based diet, by investigating and applying novel membrane technology. Currently, the only way of reducing sugars is conversion into alcohol or acids and subsequent removal, resulting in reduced nutritional value due to micronutrient oxidation and degradation of bio-active proteins. Reduction of sugars will provide healthier variants, improve glycemic index and balance protein/carbohydrate/fiber ratios, which are problematic in many plant foods due to low protein/fiber content. Similarly, direct acid removal from juices or fermented foods will reduce risk of dental damage. Finally, any food and beverages produced by yeast fermentation could benefit from selective alcohol removal. The challenges will be to develop and eventually improve membrane selectivity for the proposed targets, optimize flux potential, reduce fouling and increase chemical resistance during cleaning. Since the membrane composition is a key element in achieving the proposed results, a cross functional collaboration is necessary. GO membrane tasks will be addressed by the Graphene Engineering and Innovation Centre at UoM (UK) and DTU (DK) using state-of-the-art facilities equipped with different microscopies, electronic/optical measuring, Nanoscale Thermal Analysis, and chemical modification capabilities. Process understanding, validation and evaluation will take place at Carlsberg Research Laboratory (CRL) utilizing extensive analytical, fermentation, and beverage capabilities. As part of SYLPLANT, the consortium will work on the sequent objectives for the next three years: • Constructing & operating Arbiom’s first plant in France to reach 10,000 ton per year of ingredient production. • Validating the use of SylPro® in feed applications including aquafeed and petfood and insights. gathering consumer Figure 1: Arbiom’s first plant design • Developing the next generation of foods such as cheese analogs, meat-analogs, and specialized nutrition products with Arbiom’s ingredient. | D15: airtable | E15: 19980675 | F15: 19980675 | G15: DKK | H15: 2912812 | I15: 0 | J15: =E15*0.13 -> 2597487.8 | K15: =F15*0.13 -> 2597487.8 | L15: Awarded | M15: checked | N15: https://www.carlsbergfondet.dk/en/Forskningsaktiviteter/Bevillingsstatistik/Bevillingsoversigt/CF21_0677_Birgitte-Skadhauge | O15: need to check | R15: Original award amount is DKK 19,980,675. | T15: Birgitte Skadhauge | U15: n/a | V15: Carlsberg Research Laboratory | W15: For profit | X15: Denmark | Y15: Europe | Z15: n/a | AD15: University of Manchester, Technical University of Denmark | AE15: Yes | AI15: 44348 | AJ15: 3 | AK15: Completed | AL15: 970937 | AM15: Carlsberg Foundation | AO15: TRL 1-3 | AQ15: Non-profit | AR15: Denmark | AS15: Europe | AT15: Plant-based | AW15: Research and development | AX15: =IFERROR(INDEX('full database 2024'!AR:AR, MATCH(A15, 'full database 2024'!B:B, 0)), "") | AZ15: Ingredient optimisation | BD15: 45421 | BE15: 45448 | BI15: Tier 4 (No GFI involvement) | BJ15: 2021 | BK15: 2024 | BL15: =BK15-BJ15+1 -> 4 | BM15: =TEXTJOIN(", ", TRUE, SEQUENCE(1, BL15, BJ15)) -> 2021, 2022, 2023, 2024 | BN15: =IF(ISNUMBER(SEARCH(BN$1, $BM15)), ($K15/$BL15), "") | BO15: =IF(ISNUMBER(SEARCH(BO$1, $BM15)), ($K15/$BL15), "") -> 649371.94 | BP15: =IF(ISNUMBER(SEARCH(BP$1, $BM15)), ($K15/$BL15), "") -> 649371.94 | BQ15: =IF(ISNUMBER(SEARCH(BQ$1, $BM15)), ($K15/$BL15), "") -> 649371.94 | BR15: =IF(ISNUMBER(SEARCH(BR$1, $BM15)), ($K15/$BL15), "") -> 649371.94 | BS15: =IF(ISNUMBER(SEARCH(BS$1, $BM15)), ($K15/$BL15), "") | BT15: =IF(ISNUMBER(SEARCH(BT$1, $BM15)), ($K15/$BL15), "") | BU15: =IF(ISNUMBER(SEARCH(BU$1, $BM15)), ($K15/$BL15), "") | ... CC15: =IF(ISNUMBER(SEARCH(CC$1, $BM15)), ($K15/$BL15), "")
A16: Cellular food for sustainable production and innovative food concepts (CellFood) | B16: - With CellFood, we can, over the next five years, support the development of projects ranging from technological solutions to consumer acceptance. This will generate more knowledge on both the development of cellular foods and how we – over time – will be able to sell the products to the consumers. One thing is to make the products, another thing is to encourage people that the products are something they should consider being a part of their future, sustainable diet. | D16: airtable | E16: 15000000 | F16: 15000000 | G16: DKK | H16: 2135505 | I16: 0 | J16: =E16*0.13 -> 1950000 | K16: =F16*0.13 -> 1950000 | L16: Awarded | M16: checked | N16: https://dca.au.dk/en/current-news/news/show/artikel/institut-for-foedevarer-saetter-skub-i-udviklingen-af-cellulaere-foedevarer | O16: n/a | R16: Original award amount is DKK 15,000,000. | S16: GFI U.S. and GFI Europe provided letters of support. | T16: Jette Feveile Young | U16: Food Science | V16: Aarhus University | W16: University | X16: Denmark | Y16: Europe | Z16: n/a | AC16: Liisa Lähteenmäki; Stig Purup; Esben Skipper Sørensen; Clarissa Schwab; Steen Brock; Stella Spanou; Jesper Emborg; Mogens Sandø Lund | AD16: Aarhus University | AE16: No | AF16: 44321 | AG16: 2021 | AI16: 44774 | AJ16: 4 | AK16: In progress | AL16: 533876 | AM16: Aarhus University Research Foundation (AUFF) | AQ16: Non-profit | AR16: Denmark | AS16: Europe | AT16: Cross-cutting | AU16: CellAg | AW16: Research and development, Education and training | AX16: =IFERROR(INDEX('full database 2024'!AR:AR, MATCH(A16, 'full database 2024'!B:B, 0)), "") | AZ16: Cell line development | BD16: 44980 | BE16: 45566 | BF16: checked | BG16: https://docs.google.com/document/d/1tLlVtTn3KFv7qG4X8ZMC2gpJaQ1j-sRhGUMvrdp5kOM/edit?usp=share_link | BI16: Tier 3 (Minimal GFI involvement, e.g. LoS) | BJ16: 2022 | BK16: 2026 | BL16: =BK16-BJ16+1 -> 5 | BM16: =TEXTJOIN(", ", TRUE, SEQUENCE(1, BL16, BJ16)) -> 2022, 2023, 2024, 2025, 2026 | BN16: =IF(ISNUMBER(SEARCH(BN$1, $BM16)), ($K16/$BL16), "") | BO16: =IF(ISNUMBER(SEARCH(BO$1, $BM16)), ($K16/$BL16), "") | BP16: =IF(ISNUMBER(SEARCH(BP$1, $BM16)), ($K16/$BL16), "") -> 390000 | BQ16: =IF(ISNUMBER(SEARCH(BQ$1, $BM16)), ($K16/$BL16), "") -> 390000 | BR16: =IF(ISNUMBER(SEARCH(BR$1, $BM16)), ($K16/$BL16), "") -> 390000 | BS16: =IF(ISNUMBER(SEARCH(BS$1, $BM16)), ($K16/$BL16), "") -> 390000 | BT16: =IF(ISNUMBER(SEARCH(BT$1, $BM16)), ($K16/$BL16), "") -> 390000 | BU16: =IF(ISNUMBER(SEARCH(BU$1, $BM16)), ($K16/$BL16), "") | ... CC16: =IF(ISNUMBER(SEARCH(CC$1, $BM16)), ($K16/$BL16), "")
A17: Microbial Food Hub | B17: We propose the creation of an Engineering Biology Hub for Microbial Foods. The aim of the Hub is to harness the joint potential of two important scientific fields - engineering biology and microbial foods - in order to transform our existing food production system into one that is better for the environment, more resilient to climatic or political shocks, and that gives consumers healthier and tastier products. Background: Current food systems are unsustainable. Traditional farming and agriculture contribute significantly to climate change, and this is exacerbated by the alarming levels of food waste. Damage to the planet is mirrored by impacts on human health: a significant portion of the global population suffers malnutrition, while diseases linked to ultra-processed and high-calorie diets continue to rise. The way we produce and consume food has to change, and to change quickly if we are to have any chance of meeting targets for clean growth. Microbial foods - produced by microorganisms like yeast and fungi - offer a way to make this urgently needed transformation. Microbial foods are produced using different types of fermentation, with this process employed to produce large quantities of protein and other nutrients (biomass fermentation), to modulate and process plant and animal-derived products (traditional fermentation) or to produce new food ingredients (precision fermentation). Microbes grow rapidly, don't need large amounts of land or water to grow, and can use food by-products ('food waste') as feedstocks. In addition, microbial foods are less affected by adverse weather and can be produced locally - reducing transport costs, carbon footprint, and our dependence on food imports. Engineering biology applies engineering principles to biology, enabling scientists to build and manufacture novel biological systems and products. Tools from engineering biology have recently been applied to optimise microbial food production, and microbes can now be manipulated to be more productive, tastier and more nutritious. Applying engineering biology to microbial foods has the potential to radically change the way food is produced, and this creates an important and timely opportunity to address some of the most critical health and sustainability challenges of our time. The Hub: The first of its kind in the world, the new Hub will build on the UK's world-leading expertise and facilities in engineering biology and microbial foods. It will bring together academics, industrial partners, food organisations and consumers in a wide-ranging and ambitious programme of work that creates a clear route from scientific research to new food products on the shelf. At the heart of the Hub's activity will be eleven research projects, each addressing a separate challenge that needs to be overcome if large-scale production of diverse microbial food products is to be achieved. Project will use cutting-edge engineering biology methods, and will benefit from the Hub's additional focus on education, regulation and commercialisation, to ensure research outputs are translated into meaningful benefits. Overall, our objectives are : - To advance research into how engineering biology can be used to produce microbial foods - To develop new capabilities for developing microbial foods using engineering biology - To open new routes for this research to benefit human health and environmental sustainability Meeting these objectives will establish the Hub as an internationally-recognised reference for research, innovation and translation in the application of engineering biology to microbial foods - demonstrating UK leadership in this field, attracting the best global talent, and delivering more sustainable, productive, resilient and healthy food systems. Technical Summary We propose an Engineering Biology Hub for Microbial Foods, integrating world-leading research and innovation, education, translation and commercialisation. The overarching vision is to harness the joint potentials of engineering biology and the microbial food revolution to create and deliver a more sustainable, productive, resilient and healthy food system. The Hub's research programme encompasses projects focused on 'Applications' (biomass fermentation, traditional fermentation, precision fermentation), and 'Capabilities' (scale-up, artificial intelligence, strain engineering, food technology and nutrition) at the interface of engineering biology and microbial foods. Projects will be underpinned by a range of cutting-edge tools and approaches from engineering biology, including automation, microbial community design, bioprocessing, modelling, systems biology and strain engineering. To ensure research outputs are translated into meaningful change, projects are complemented by a range of different 'Paths' (e.g. commercialisation, education, regulation, communication, etc). The Hub's objectives across these areas are: 'Applications': To advance engineering biology research to produce microbial foods. 'Capabilities': To develop new capabilities for the development of microbial foods using engineering biology (for the members of the Hub and beyond). 'Paths': To support present and future research into engineering biology for microbial foods, and translation of this research into positive, real-world impacts. Meeting these three objectives will establish UK leadership in the field, with the Hub an internationally-recognised reference for this application of engineering biology. | D17: airtable | E17: 14000000 | F17: 12634909 | G17: GBP | H17: 17427480 | I17: 14937840 | J17: =E17*1.19 -> 16660000 | K17: =F17*1.19 -> 15035542 | L17: Awarded | M17: checked | N17: https://www.foodingredientsfirst.com/news/uk-government-injects-%C2%A312m-into-microbial-food-hub-for-alt-protein-innovation.html | O17: grant.14049711 | T17: Rodrigo Ledesma-Amaro | V17: Imperial College London | W17: University | X17: UK | Y17: Europe | AC17: Professors Paul Freemont (Department of Infectious Disease), Karen Polizzi (Department of Chemical Engineering), Gary Frost (Department of Metabolism, Digestion and Reproduction), Tom Ellis (Department of Bioengineering) and Geoff Baldwin (Department of Life Sciences). | AE17: No | AH17: 45331 | AI17: 45383 | AJ17: 5 | AK17: In progress | AL17: 3485496 | AM17: UK Research and Innovation (UKRI) | AN17: Biotechnology and Biological Sciences Research Council (BBSRC) | AQ17: Government | AR17: United Kingdom | AS17: Europe | AT17: Fermentation | AU17: PF | AW17: Research and development | AX17: =IFERROR(INDEX('full database 2024'!AR:AR, MATCH(A17, 'full database 2024'!B:B, 0)), "") | AZ17: cross-cutting | BD17: 45406 | BE17: 45779 | BF17: checked | BG17: https://docs.google.com/document/d/197_vHTSaVQSB77rGsyhQRGBpcoXMK26A/edit | BH17: checked | BJ17: 2024 | BK17: 2029 | BL17: =BK17-BJ17+1 -> 6 | BM17: =TEXTJOIN(", ", TRUE, SEQUENCE(1, BL17, BJ17)) -> 2024, 2025, 2026, 2027, 2028, 2029 | BN17: =IF(ISNUMBER(SEARCH(BN$1, $BM17)), ($K17/$BL17), "") | BO17: =IF(ISNUMBER(SEARCH(BO$1, $BM17)), ($K17/$BL17), "") | BP17: =IF(ISNUMBER(SEARCH(BP$1, $BM17)), ($K17/$BL17), "") | BQ17: =IF(ISNUMBER(SEARCH(BQ$1, $BM17)), ($K17/$BL17), "") | BR17: =IF(ISNUMBER(SEARCH(BR$1, $BM17)), ($K17/$BL17), "") -> 2505923.6 | BS17: =IF(ISNUMBER(SEARCH(BS$1, $BM17)), ($K17/$BL17), "") -> 2505923.6 | BT17: =IF(ISNUMBER(SEARCH(BT$1, $BM17)), ($K17/$BL17), "") -> 2505923.6 | BU17: =IF(ISNUMBER(SEARCH(BU$1, $BM17)), ($K17/$BL17), "") -> 2505923.6 | ... CC17: =IF(ISNUMBER(SEARCH(CC$1, $BM17)), ($K17/$BL17), "")
